{
    "registryname": "blood_resonator",
    "localizedname": "Blood Resonator",
    "color": "c63342",
    "parts": [
        {
            "x": -1,
            "y": 2,
            "z": 0,
            "elements": [
                "bloodmagic:blood_rune@0"
            ]
        },
        {
            "x": 0,
            "y": 3,
            "z": 1,
            "elements": [
                "bloodmagic:demon_crystal@0"
            ]
        },
        {
            "x": -2,
            "y": -2,
            "z": 4,
            "elements": [
                "bloodmagic:blood_rune@0"
            ]
        },
        {
            "x": 0,
            "y": -2,
            "z": 0,
            "elements": [
                "bloodmagic:blood_rune@0"
            ]
        },
        {
            "x": -3,
            "y": -2,
            "z": 1,
            "elements": [
                "bloodmagic:blood_rune@0"
            ]
        },
        {
            "x": 2,
            "y": 1,
            "z": 2,
            "elements": [
                "bloodtinker:blood_bronze_block@0"
            ]
        },
        {
            "x": 0,
            "y": 2,
            "z": 1,
            "elements": [
                "bloodmagic:blood_rune@0"
            ]
        },
        {
            "x": -1,
            "y": 1,
            "z": 0,
            "elements": [
                "bloodmagic:blood_rune@0"
            ]
        },
        {
            "x": 0,
            "y": -1,
            "z": 0,
            "elements": [
                "bloodtinker:blood_bronze_block@0"
            ]
        },
        {
            "x": 3,
            "y": 2,
            "z": 2,
            "elements": [
                "bloodmagic:blood_rune@0"
            ]
        },
        {
            "x": -2,
            "y": -2,
            "z": 3,
            "elements": [
                "bloodmagic:blood_rune@0"
            ]
        },
        {
            "x": -1,
            "y": 0,
            "z": 4,
            "elements": [
                "bloodmagic:blood_rune@0"
            ]
        },
        {
            "x": 3,
            "y": -2,
            "z": 2,
            "elements": [
                "bloodmagic:blood_rune@0"
            ]
        },
        {
            "x": 2,
            "y": -2,
            "z": -1,
            "elements": [
                "bloodmagic:blood_rune@0"
            ]
        },
        {
            "x": 2,
            "y": 0,
            "z": 2,
            "elements": [
                "modularmachinery:blockinputbus"
            ]
        },
        {
            "x": 1,
            "y": 0,
            "z": 0,
            "elements": [
                "bloodmagic:blood_rune@0"
            ]
        },
        {
            "x": 2,
            "y": -2,
            "z": 1,
            "elements": [
                "bloodmagic:blood_rune@0"
            ]
        },
        {
            "x": 1,
            "y": -2,
            "z": 0,
            "elements": [
                "bloodmagic:blood_rune@0"
            ]
        },
        {
            "x": -2,
            "y": 2,
            "z": 0,
            "elements": [
                "bloodmagic:blood_rune@0"
            ]
        },
        {
            "x": 1,
            "y": -2,
            "z": 4,
            "elements": [
                "bloodmagic:blood_rune@0"
            ]
        },
        {
            "x": -1,
            "y": 1,
            "z": 4,
            "elements": [
                "bloodmagic:blood_rune@0"
            ]
        },
        {
            "x": 0,
            "y": 0,
            "z": 1,
            "elements": [
                "thaumcraft:flesh_block@0"
            ]
        },
        {
            "x": -3,
            "y": 2,
            "z": 1,
            "elements": [
                "bloodmagic:blood_rune@0"
            ]
        },
        {
            "x": 1,
            "y": -1,
            "z": 0,
            "elements": [
                "bloodmagic:blood_rune@0"
            ]
        },
        {
            "x": -2,
            "y": 2,
            "z": 5,
            "elements": [
                "bloodmagic:blood_rune@0"
            ]
        },
        {
            "x": 2,
            "y": 2,
            "z": 2,
            "elements": [
                "bloodmagic:blood_rune@0"
            ]
        },
        {
            "x": -1,
            "y": 2,
            "z": 4,
            "elements": [
                "bloodmagic:blood_rune@0"
            ]
        },
        {
            "x": -1,
            "y": -2,
            "z": -1,
            "elements": [
                "bloodmagic:blood_rune@0"
            ]
        },
        {
            "x": 1,
            "y": -2,
            "z": 3,
            "elements": [
                "bloodmagic:blood_rune@0"
            ]
        },
        {
            "x": 2,
            "y": -1,
            "z": 1,
            "elements": [
                "bloodmagic:blood_rune@0"
            ]
        },
        {
            "x": 2,
            "y": -2,
            "z": 2,
            "elements": [
                "bloodmagic:blood_rune@0"
            ]
        },
        {
            "x": 1,
            "y": 2,
            "z": 0,
            "elements": [
                "bloodmagic:blood_rune@0"
            ]
        },
        {
            "x": 0,
            "y": -2,
            "z": 4,
            "elements": [
                "bloodmagic:blood_rune@0"
            ]
        },
        {
            "x": -1,
            "y": -2,
            "z": 1,
            "elements": [
                "bloodmagic:blood_rune@0"
            ]
        },
        {
            "x": -2,
            "y": -2,
            "z": 0,
            "elements": [
                "bloodmagic:blood_rune@0"
            ]
        },
        {
            "x": -1,
            "y": -2,
            "z": 5,
            "elements": [
                "bloodmagic:blood_rune@0"
            ]
        },
        {
            "x": -2,
            "y": 2,
            "z": 1,
            "elements": [
                "bloodmagic:blood_rune@0"
            ]
        },
        {
            "x": 2,
            "y": 2,
            "z": 3,
            "elements": [
                "bloodmagic:blood_rune@0"
            ]
        },
        {
            "x": 2,
            "y": -1,
            "z": 2,
            "elements": [
                "bloodtinker:blood_bronze_block@0"
            ]
        },
        {
            "x": 0,
            "y": 1,
            "z": 2,
            "elements": [
                "thaumcraft:flesh_block@0"
            ]
        },
        {
            "x": 1,
            "y": 1,
            "z": 0,
            "elements": [
                "bloodmagic:blood_rune@0"
            ]
        },
        {
            "x": -1,
            "y": 2,
            "z": -1,
            "elements": [
                "bloodmagic:blood_rune@0"
            ]
        },
        {
            "x": 2,
            "y": 0,
            "z": 3,
            "elements": [
                "bloodmagic:blood_rune@0"
            ]
        },
        {
            "x": 2,
            "y": 1,
            "z": 3,
            "elements": [
                "bloodmagic:blood_rune@0"
            ]
        },
        {
            "x": -3,
            "y": -2,
            "z": 2,
            "elements": [
                "bloodmagic:blood_rune@0"
            ]
        },
        {
            "x": 0,
            "y": -2,
            "z": -1,
            "elements": [
                "bloodmagic:blood_rune@0"
            ]
        },
        {
            "x": 0,
            "y": 0,
            "z": 2,
            "elements": [
                "thaumcraft:flesh_block@0"
            ]
        },
        {
            "x": -3,
            "y": 2,
            "z": 2,
            "elements": [
                "bloodmagic:blood_rune@0"
            ]
        },
        {
            "x": -2,
            "y": 2,
            "z": 4,
            "elements": [
                "bloodmagic:blood_rune@0"
            ]
        },
        {
            "x": -1,
            "y": 0,
            "z": 0,
            "elements": [
                "bloodmagic:blood_rune@0"
            ]
        },
        {
            "x": -2,
            "y": 0,
            "z": 1,
            "elements": [
                "bloodmagic:blood_rune@0"
            ]
        },
        {
            "x": 3,
            "y": -2,
            "z": 0,
            "elements": [
                "bloodmagic:blood_rune@0"
            ]
        },
        {
            "x": -1,
            "y": -2,
            "z": 4,
            "elements": [
                "bloodmagic:blood_rune@0"
            ]
        },
        {
            "x": 0,
            "y": -2,
            "z": 1,
            "elements": [
                "bloodmagic:blood_rune@0"
            ]
        },
        {
            "x": 2,
            "y": -2,
            "z": 5,
            "elements": [
                "bloodmagic:blood_rune@0"
            ]
        },
        {
            "x": 2,
            "y": -1,
            "z": 3,
            "elements": [
                "bloodmagic:blood_rune@0"
            ]
        },
        {
            "x": -1,
            "y": 2,
            "z": 1,
            "elements": [
                "bloodmagic:blood_rune@0"
            ]
        },
        {
            "x": 1,
            "y": 2,
            "z": 3,
            "elements": [
                "bloodmagic:blood_rune@0"
            ]
        },
        {
            "x": 0,
            "y": 2,
            "z": 5,
            "elements": [
                "bloodmagic:blood_rune@0"
            ]
        },
        {
            "x": 0,
            "y": 2,
            "z": -1,
            "elements": [
                "bloodmagic:blood_rune@0"
            ]
        },
        {
            "x": -2,
            "y": 1,
            "z": 1,
            "elements": [
                "bloodmagic:blood_rune@0"
            ]
        },
        {
            "x": 3,
            "y": -2,
            "z": 3,
            "elements": [
                "bloodmagic:blood_rune@0"
            ]
        },
        {
            "x": 0,
            "y": 3,
            "z": 3,
            "elements": [
                "bloodmagic:demon_crystal@0"
            ]
        },
        {
            "x": 0,
            "y": 2,
            "z": 2,
            "elements": [
                "modularmachinery:blockwillproviderinput"
            ]
        },
        {
            "x": 1,
            "y": -2,
            "z": -1,
            "elements": [
                "bloodmagic:blood_rune@0"
            ]
        },
        {
            "x": -3,
            "y": 2,
            "z": 4,
            "elements": [
                "bloodmagic:blood_rune@0"
            ]
        },
        {
            "x": 0,
            "y": -2,
            "z": 2,
            "elements": [
                "bloodmagic:blood_rune@0"
            ]
        },
        {
            "x": 1,
            "y": -2,
            "z": 1,
            "elements": [
                "bloodmagic:blood_rune@0"
            ]
        },
        {
            "x": -2,
            "y": 0,
            "z": 2,
            "elements": [
                "modularmachinery:blockoutputbus"
            ]
        },
        {
            "x": -1,
            "y": 3,
            "z": 2,
            "elements": [
                "bloodmagic:demon_crystal@0"
            ]
        },
        {
            "x": 1,
            "y": -2,
            "z": 5,
            "elements": [
                "bloodmagic:blood_rune@0"
            ]
        },
        {
            "x": 2,
            "y": -2,
            "z": 4,
            "elements": [
                "bloodmagic:blood_rune@0"
            ]
        },
        {
            "x": 3,
            "y": 2,
            "z": 0,
            "elements": [
                "bloodmagic:blood_rune@0"
            ]
        },
        {
            "x": -2,
            "y": 1,
            "z": 2,
            "elements": [
                "bloodtinker:blood_bronze_block@0"
            ]
        },
        {
            "x": 1,
            "y": 2,
            "z": 5,
            "elements": [
                "bloodmagic:blood_rune@0"
            ]
        },
        {
            "x": 0,
            "y": 1,
            "z": 4,
            "elements": [
                "bloodtinker:blood_bronze_block@0"
            ]
        },
        {
            "x": -3,
            "y": 2,
            "z": 3,
            "elements": [
                "bloodmagic:blood_rune@0"
            ]
        },
        {
            "x": 0,
            "y": -1,
            "z": 2,
            "elements": [
                "thaumcraft:flesh_block@0"
            ]
        },
        {
            "x": 0,
            "y": 0,
            "z": 3,
            "elements": [
                "thaumcraft:flesh_block@0"
            ]
        },
        {
            "x": -1,
            "y": -1,
            "z": 4,
            "elements": [
                "bloodmagic:blood_rune@0"
            ]
        },
        {
            "x": -1,
            "y": 2,
            "z": 2,
            "elements": [
                "bloodmagic:blood_rune@0"
            ]
        },
        {
            "x": -2,
            "y": -2,
            "z": -1,
            "elements": [
                "bloodmagic:blood_rune@0"
            ]
        },
        {
            "x": 0,
            "y": 2,
            "z": 4,
            "elements": [
                "bloodmagic:blood_rune@0"
            ]
        },
        {
            "x": 2,
            "y": -2,
            "z": 3,
            "elements": [
                "bloodmagic:blood_rune@0"
            ]
        },
        {
            "x": -3,
            "y": -2,
            "z": 4,
            "elements": [
                "bloodmagic:blood_rune@0"
            ]
        },
        {
            "x": 2,
            "y": 2,
            "z": 0,
            "elements": [
                "bloodmagic:blood_rune@0"
            ]
        },
        {
            "x": -1,
            "y": -2,
            "z": 2,
            "elements": [
                "bloodmagic:blood_rune@0"
            ]
        },
        {
            "x": 0,
            "y": -2,
            "z": 5,
            "elements": [
                "bloodmagic:blood_rune@0"
            ]
        },
        {
            "x": -2,
            "y": -2,
            "z": 1,
            "elements": [
                "bloodmagic:blood_rune@0"
            ]
        },
        {
            "x": -3,
            "y": -2,
            "z": 0,
            "elements": [
                "bloodmagic:blood_rune@0"
            ]
        },
        {
            "x": 1,
            "y": 2,
            "z": -1,
            "elements": [
                "bloodmagic:blood_rune@0"
            ]
        },
        {
            "x": 1,
            "y": 2,
            "z": 1,
            "elements": [
                "bloodmagic:blood_rune@0"
            ]
        },
        {
            "x": 3,
            "y": 2,
            "z": 3,
            "elements": [
                "bloodmagic:blood_rune@0"
            ]
        },
        {
            "x": 2,
            "y": 2,
            "z": 5,
            "elements": [
                "bloodmagic:blood_rune@0"
            ]
        },
        {
            "x": 3,
            "y": 2,
            "z": 4,
            "elements": [
                "bloodmagic:blood_rune@0"
            ]
        },
        {
            "x": -2,
            "y": -1,
            "z": 1,
            "elements": [
                "bloodmagic:blood_rune@0"
            ]
        },
        {
            "x": 0,
            "y": 2,
            "z": 3,
            "elements": [
                "bloodmagic:blood_rune@0"
            ]
        },
        {
            "x": -2,
            "y": 2,
            "z": -1,
            "elements": [
                "bloodmagic:blood_rune@0"
            ]
        },
        {
            "x": -3,
            "y": -2,
            "z": 3,
            "elements": [
                "bloodmagic:blood_rune@0"
            ]
        },
        {
            "x": -2,
            "y": 2,
            "z": 2,
            "elements": [
                "bloodmagic:blood_rune@0"
            ]
        },
        {
            "x": 0,
            "y": 0,
            "z": 4,
            "elements": [
                "modularmachinery:blockfluidinputhatch"
            ]
        },
        {
            "x": -1,
            "y": 0,
            "z": 2,
            "elements": [
                "thaumcraft:flesh_block@0"
            ]
        },
        {
            "x": 3,
            "y": -2,
            "z": 1,
            "elements": [
                "bloodmagic:blood_rune@0"
            ]
        },
        {
            "x": 2,
            "y": -2,
            "z": 0,
            "elements": [
                "bloodmagic:blood_rune@0"
            ]
        },
        {
            "x": -3,
            "y": 2,
            "z": 0,
            "elements": [
                "bloodmagic:blood_rune@0"
            ]
        },
        {
            "x": 2,
            "y": 2,
            "z": -1,
            "elements": [
                "bloodmagic:blood_rune@0"
            ]
        },
        {
            "x": -2,
            "y": -2,
            "z": 2,
            "elements": [
                "bloodmagic:blood_rune@0"
            ]
        },
        {
            "x": 1,
            "y": 3,
            "z": 2,
            "elements": [
                "bloodmagic:demon_crystal@0"
            ]
        },
        {
            "x": 0,
            "y": -1,
            "z": 4,
            "elements": [
                "bloodtinker:blood_bronze_block@0"
            ]
        },
        {
            "x": 2,
            "y": 2,
            "z": 4,
            "elements": [
                "bloodmagic:blood_rune@0"
            ]
        },
        {
            "x": -2,
            "y": -1,
            "z": 2,
            "elements": [
                "bloodtinker:blood_bronze_block@0"
            ]
        },
        {
            "x": -1,
            "y": 2,
            "z": 5,
            "elements": [
                "bloodmagic:blood_rune@0"
            ]
        },
        {
            "x": -1,
            "y": 2,
            "z": 3,
            "elements": [
                "bloodmagic:blood_rune@0"
            ]
        },
        {
            "x": 2,
            "y": 2,
            "z": 1,
            "elements": [
                "bloodmagic:blood_rune@0"
            ]
        },
        {
            "x": 3,
            "y": -2,
            "z": 4,
            "elements": [
                "bloodmagic:blood_rune@0"
            ]
        },
        {
            "x": 1,
            "y": 0,
            "z": 4,
            "elements": [
                "bloodmagic:blood_rune@0"
            ]
        },
        {
            "x": 1,
            "y": 2,
            "z": 2,
            "elements": [
                "bloodmagic:blood_rune@0"
            ]
        },
        {
            "x": -2,
            "y": 0,
            "z": 3,
            "elements": [
                "bloodmagic:blood_rune@0"
            ]
        },
        {
            "x": 0,
            "y": -2,
            "z": 3,
            "elements": [
                "bloodmagic:blood_rune@0"
            ]
        },
        {
            "x": -2,
            "y": -2,
            "z": 5,
            "elements": [
                "bloodmagic:blood_rune@0"
            ]
        },
        {
            "x": 1,
            "y": -2,
            "z": 2,
            "elements": [
                "bloodmagic:blood_rune@0"
            ]
        },
        {
            "x": 0,
            "y": 2,
            "z": 0,
            "elements": [
                "bloodmagic:blood_rune@0"
            ]
        },
        {
            "x": -1,
            "y": -2,
            "z": 0,
            "elements": [
                "bloodmagic:blood_rune@0"
            ]
        },
        {
            "x": -2,
            "y": 1,
            "z": 3,
            "elements": [
                "bloodmagic:blood_rune@0"
            ]
        },
        {
            "x": 1,
            "y": -1,
            "z": 4,
            "elements": [
                "bloodmagic:blood_rune@0"
            ]
        },
        {
            "x": -2,
            "y": -1,
            "z": 3,
            "elements": [
                "bloodmagic:blood_rune@0"
            ]
        },
        {
            "x": 2,
            "y": 0,
            "z": 1,
            "elements": [
                "bloodmagic:blood_rune@0"
            ]
        },
        {
            "x": 1,
            "y": 1,
            "z": 4,
            "elements": [
                "bloodmagic:blood_rune@0"
            ]
        },
        {
            "x": -2,
            "y": 2,
            "z": 3,
            "elements": [
                "bloodmagic:blood_rune@0"
            ]
        },
        {
            "x": 0,
            "y": 1,
            "z": 0,
            "elements": [
                "bloodtinker:blood_bronze_block@0"
            ]
        },
        {
            "x": -1,
            "y": -1,
            "z": 0,
            "elements": [
                "bloodmagic:blood_rune@0"
            ]
        },
        {
            "x": 1,
            "y": 2,
            "z": 4,
            "elements": [
                "bloodmagic:blood_rune@0"
            ]
        },
        {
            "x": 3,
            "y": 2,
            "z": 1,
            "elements": [
                "bloodmagic:blood_rune@0"
            ]
        },
        {
            "x": -1,
            "y": -2,
            "z": 3,
            "elements": [
                "bloodmagic:blood_rune@0"
            ]
        },
        {
            "x": 2,
            "y": 1,
            "z": 1,
            "elements": [
                "bloodmagic:blood_rune@0"
            ]
        },
        {
            "x": 1,
            "y": 0,
            "z": 2,
            "elements": [
                "thaumcraft:flesh_block@0"
            ]
        }
    ]}