{
    "registryname": "emptiness_energizer",
    "localizedname": "Emptiness Energizer",
    "color": "2a2042",
    "parts": [
        {
            "x": 0,
            "y": 0,
            "z": 0,
            "elements": [
                "modularmachinery:blockcontroller@2"
            ]
        },
        {
            "x": -5,
            "y": 4,
            "z": 10,
            "elements": [
                "thaumadditions:brass_plated_silverwood@0"
            ]
        },
        {
            "x": 5,
            "y": 4,
            "z": 8,
            "elements": [
                "thaumicaugmentation:fortified_glass@0"
            ]
        },
        {
            "x": -1,
            "y": 2,
            "z": 0,
            "elements": [
                "thaumicaugmentation:fortified_glass@0"
            ]
        },
        {
            "x": 5,
            "y": 1,
            "z": 1,
            "elements": [
                "thaumicaugmentation:fortified_glass@0"
            ]
        },
        {
            "x": -5,
            "y": 9,
            "z": 0,
            "elements": [
                "thaumadditions:brass_plated_silverwood@0"
            ]
        },
        {
            "x": -2,
            "y": 4,
            "z": 0,
            "elements": [
                "thaumicaugmentation:fortified_glass@0"
            ]
        },
        {
            "x": -5,
            "y": 6,
            "z": 5,
            "elements": [
                "thaumicaugmentation:fortified_glass@0"
            ]
        },
        {
            "x": 5,
            "y": 0,
            "z": 1,
            "elements": [
                "thaumcraft:metal_thaumium@0"
            ]
        },
        {
            "x": 0,
            "y": 9,
            "z": 3,
            "elements": [
                "thaumicaugmentation:fortified_glass@0"
            ]
        },
        {
            "x": -5,
            "y": 3,
            "z": 10,
            "elements": [
                "thaumadditions:brass_plated_silverwood@0"
            ]
        },
        {
            "x": -1,
            "y": 1,
            "z": 0,
            "elements": [
                "thaumicaugmentation:fortified_glass@0"
            ]
        },
        {
            "x": -3,
            "y": 6,
            "z": 0,
            "elements": [
                "thaumicaugmentation:fortified_glass@0"
            ]
        },
        {
            "x": -4,
            "y": 8,
            "z": 0,
            "elements": [
                "thaumcraft:metal_thaumium@0"
            ]
        },
        {
            "x": 0,
            "y": -1,
            "z": 0,
            "elements": [
                "thaumadditions:brass_plated_silverwood@0"
            ]
        },
        {
            "x": -5,
            "y": 2,
            "z": 10,
            "elements": [
                "thaumadditions:brass_plated_silverwood@0"
            ]
        },
        {
            "x": 5,
            "y": 3,
            "z": 8,
            "elements": [
                "thaumicaugmentation:fortified_glass@0"
            ]
        },
        {
            "x": -2,
            "y": 3,
            "z": 0,
            "elements": [
                "thaumicaugmentation:fortified_glass@0"
            ]
        },
        {
            "x": 5,
            "y": 7,
            "z": 1,
            "elements": [
                "thaumicaugmentation:fortified_glass@0"
            ]
        },
        {
            "x": -5,
            "y": 0,
            "z": 6,
            "elements": [
                "thaumcraft:metal_thaumium@0"
            ]
        },
        {
            "x": -3,
            "y": -1,
            "z": 5,
            "elements": [
                "thaumicaugmentation:fortified_glass@0"
            ]
        },
        {
            "x": -5,
            "y": 1,
            "z": 6,
            "elements": [
                "thaumicaugmentation:fortified_glass@0"
            ]
        },
        {
            "x": 1,
            "y": 0,
            "z": 0,
            "elements": [
                "thaumcraft:metal_thaumium@0"
            ]
        },
        {
            "x": -3,
            "y": 5,
            "z": 0,
            "elements": [
                "thaumicaugmentation:fortified_glass@0"
            ]
        },
        {
            "x": -4,
            "y": -1,
            "z": 10,
            "elements": [
                "thaumadditions:brass_plated_silverwood@0"
            ]
        },
        {
            "x": 5,
            "y": -1,
            "z": 1,
            "elements": [
                "thaumadditions:brass_plated_silverwood@0"
            ]
        },
        {
            "x": -4,
            "y": 7,
            "z": 0,
            "elements": [
                "thaumicaugmentation:fortified_glass@0"
            ]
        },
        {
            "x": 0,
            "y": 9,
            "z": 4,
            "elements": [
                "thaumicaugmentation:fortified_glass@0"
            ]
        },
        {
            "x": -5,
            "y": 5,
            "z": 5,
            "elements": [
                "thaumicaugmentation:fortified_glass@0"
            ]
        },
        {
            "x": 5,
            "y": 3,
            "z": 1,
            "elements": [
                "thaumicaugmentation:fortified_glass@0"
            ]
        },
        {
            "x": -2,
            "y": 2,
            "z": 0,
            "elements": [
                "thaumicaugmentation:fortified_glass@0"
            ]
        },
        {
            "x": -3,
            "y": 7,
            "z": 0,
            "elements": [
                "thaumicaugmentation:fortified_glass@0"
            ]
        },
        {
            "x": -5,
            "y": 3,
            "z": 5,
            "elements": [
                "thaumicaugmentation:fortified_glass@0"
            ]
        },
        {
            "x": -5,
            "y": 1,
            "z": 10,
            "elements": [
                "thaumadditions:brass_plated_silverwood@0"
            ]
        },
        {
            "x": 5,
            "y": 1,
            "z": 8,
            "elements": [
                "thaumicaugmentation:fortified_glass@0"
            ]
        },
        {
            "x": 3,
            "y": 9,
            "z": 3,
            "elements": [
                "thaumicaugmentation:fortified_glass@0"
            ]
        },
        {
            "x": -5,
            "y": 4,
            "z": 5,
            "elements": [
                "thaumicaugmentation:fortified_glass@0"
            ]
        },
        {
            "x": -1,
            "y": 4,
            "z": 0,
            "elements": [
                "thaumicaugmentation:fortified_glass@0"
            ]
        },
        {
            "x": -4,
            "y": 6,
            "z": 0,
            "elements": [
                "thaumicaugmentation:fortified_glass@0"
            ]
        },
        {
            "x": -3,
            "y": 9,
            "z": 7,
            "elements": [
                "thaumicaugmentation:fortified_glass@0"
            ]
        },
        {
            "x": 1,
            "y": -1,
            "z": 0,
            "elements": [
                "thaumadditions:brass_plated_silverwood@0"
            ]
        },
        {
            "x": -2,
            "y": 1,
            "z": 0,
            "elements": [
                "thaumicaugmentation:fortified_glass@0"
            ]
        },
        {
            "x": -3,
            "y": 8,
            "z": 0,
            "elements": [
                "thaumcraft:metal_thaumium@0"
            ]
        },
        {
            "x": -1,
            "y": 9,
            "z": 1,
            "elements": [
                "thaumicaugmentation:fortified_glass@0"
            ]
        },
        {
            "x": -5,
            "y": 0,
            "z": 10,
            "elements": [
                "thaumadditions:brass_plated_silverwood@0"
            ]
        },
        {
            "x": 5,
            "y": 2,
            "z": 8,
            "elements": [
                "thaumicaugmentation:fortified_glass@0"
            ]
        },
        {
            "x": -4,
            "y": -1,
            "z": 5,
            "elements": [
                "thaumicaugmentation:fortified_glass@0"
            ]
        },
        {
            "x": 5,
            "y": 2,
            "z": 1,
            "elements": [
                "thaumicaugmentation:fortified_glass@0"
            ]
        },
        {
            "x": -1,
            "y": 3,
            "z": 0,
            "elements": [
                "thaumicaugmentation:fortified_glass@0"
            ]
        },
        {
            "x": -5,
            "y": -1,
            "z": 10,
            "elements": [
                "thaumadditions:brass_plated_silverwood@0"
            ]
        },
        {
            "x": 3,
            "y": -1,
            "z": 9,
            "elements": [
                "thaumicaugmentation:fortified_glass@0"
            ]
        },
        {
            "x": -4,
            "y": 5,
            "z": 0,
            "elements": [
                "thaumicaugmentation:fortified_glass@0"
            ]
        },
        {
            "x": 3,
            "y": 9,
            "z": 4,
            "elements": [
                "thaumicaugmentation:fortified_glass@0"
            ]
        },
        {
            "x": -2,
            "y": 9,
            "z": 9,
            "elements": [
                "thaumicaugmentation:fortified_glass@0"
            ]
        },
        {
            "x": 2,
            "y": 0,
            "z": 0,
            "elements": [
                "thaumcraft:metal_thaumium@0"
            ]
        },
        {
            "x": -4,
            "y": 1,
            "z": 10,
            "elements": [
                "thaumicaugmentation:fortified_glass@0"
            ]
        },
        {
            "x": -2,
            "y": -1,
            "z": 10,
            "elements": [
                "thaumadditions:brass_plated_silverwood@0"
            ]
        },
        {
            "x": -2,
            "y": 7,
            "z": 0,
            "elements": [
                "thaumicaugmentation:fortified_glass@0"
            ]
        },
        {
            "x": -3,
            "y": 9,
            "z": 0,
            "elements": [
                "thaumadditions:brass_plated_silverwood@0"
            ]
        },
        {
            "x": 1,
            "y": 2,
            "z": 0,
            "elements": [
                "thaumicaugmentation:fortified_glass@0"
            ]
        },
        {
            "x": -4,
            "y": 4,
            "z": 0,
            "elements": [
                "thaumicaugmentation:fortified_glass@0"
            ]
        },
        {
            "x": -5,
            "y": 0,
            "z": 5,
            "elements": [
                "modularmachinery:blockoutputbus"
            ]
        },
        {
            "x": 5,
            "y": 8,
            "z": 8,
            "elements": [
                "thaumcraft:metal_thaumium@0"
            ]
        },
        {
            "x": 5,
            "y": 7,
            "z": 8,
            "elements": [
                "thaumicaugmentation:fortified_glass@0"
            ]
        },
        {
            "x": -5,
            "y": 6,
            "z": 0,
            "elements": [
                "thaumadditions:brass_plated_silverwood@0"
            ]
        },
        {
            "x": 1,
            "y": 1,
            "z": 0,
            "elements": [
                "thaumicaugmentation:fortified_glass@0"
            ]
        },
        {
            "x": 5,
            "y": 5,
            "z": 1,
            "elements": [
                "thaumicaugmentation:fortified_glass@0"
            ]
        },
        {
            "x": -4,
            "y": 0,
            "z": 10,
            "elements": [
                "thaumcraft:metal_thaumium@0"
            ]
        },
        {
            "x": -2,
            "y": -1,
            "z": 0,
            "elements": [
                "thaumadditions:brass_plated_silverwood@0"
            ]
        },
        {
            "x": -1,
            "y": -1,
            "z": 5,
            "elements": [
                "thaumicaugmentation:fortified_glass@0"
            ]
        },
        {
            "x": -5,
            "y": 5,
            "z": 0,
            "elements": [
                "thaumadditions:brass_plated_silverwood@0"
            ]
        },
        {
            "x": -4,
            "y": 3,
            "z": 0,
            "elements": [
                "thaumicaugmentation:fortified_glass@0"
            ]
        },
        {
            "x": -5,
            "y": 2,
            "z": 5,
            "elements": [
                "thaumicaugmentation:fortified_glass@0"
            ]
        },
        {
            "x": -2,
            "y": 8,
            "z": 0,
            "elements": [
                "thaumcraft:metal_thaumium@0"
            ]
        },
        {
            "x": 2,
            "y": 9,
            "z": 1,
            "elements": [
                "thaumicaugmentation:fortified_glass@0"
            ]
        },
        {
            "x": 2,
            "y": 9,
            "z": 4,
            "elements": [
                "thaumicaugmentation:fortified_glass@0"
            ]
        },
        {
            "x": 2,
            "y": 9,
            "z": 8,
            "elements": [
                "thaumicaugmentation:fortified_glass@0"
            ]
        },
        {
            "x": -5,
            "y": 1,
            "z": 5,
            "elements": [
                "thaumicaugmentation:fortified_glass@0"
            ]
        },
        {
            "x": 5,
            "y": 4,
            "z": 1,
            "elements": [
                "thaumicaugmentation:fortified_glass@0"
            ]
        },
        {
            "x": -1,
            "y": 0,
            "z": 0,
            "elements": [
                "thaumcraft:metal_thaumium@0"
            ]
        },
        {
            "x": -4,
            "y": 2,
            "z": 0,
            "elements": [
                "thaumicaugmentation:fortified_glass@0"
            ]
        },
        {
            "x": 2,
            "y": -1,
            "z": 3,
            "elements": [
                "thaumicaugmentation:fortified_glass@0"
            ]
        },
        {
            "x": -4,
            "y": 4,
            "z": 10,
            "elements": [
                "thaumicaugmentation:fortified_glass@0"
            ]
        },
        {
            "x": 3,
            "y": 9,
            "z": 7,
            "elements": [
                "thaumicaugmentation:fortified_glass@0"
            ]
        },
        {
            "x": 1,
            "y": 4,
            "z": 0,
            "elements": [
                "thaumicaugmentation:fortified_glass@0"
            ]
        },
        {
            "x": 5,
            "y": 6,
            "z": 8,
            "elements": [
                "thaumicaugmentation:fortified_glass@0"
            ]
        },
        {
            "x": -4,
            "y": 3,
            "z": 10,
            "elements": [
                "thaumicaugmentation:fortified_glass@0"
            ]
        },
        {
            "x": 5,
            "y": -1,
            "z": 4,
            "elements": [
                "thaumadditions:brass_plated_silverwood@0"
            ]
        },
        {
            "x": -2,
            "y": 6,
            "z": 0,
            "elements": [
                "thaumicaugmentation:fortified_glass@0"
            ]
        },
        {
            "x": -3,
            "y": 9,
            "z": 3,
            "elements": [
                "thaumicaugmentation:fortified_glass@0"
            ]
        },
        {
            "x": 5,
            "y": 5,
            "z": 8,
            "elements": [
                "thaumicaugmentation:fortified_glass@0"
            ]
        },
        {
            "x": -5,
            "y": 8,
            "z": 0,
            "elements": [
                "thaumadditions:brass_plated_silverwood@0"
            ]
        },
        {
            "x": -4,
            "y": 2,
            "z": 10,
            "elements": [
                "thaumicaugmentation:fortified_glass@0"
            ]
        },
        {
            "x": -5,
            "y": 5,
            "z": 10,
            "elements": [
                "thaumadditions:brass_plated_silverwood@0"
            ]
        },
        {
            "x": 4,
            "y": 9,
            "z": 2,
            "elements": [
                "thaumicaugmentation:fortified_glass@0"
            ]
        },
        {
            "x": 1,
            "y": 3,
            "z": 0,
            "elements": [
                "thaumicaugmentation:fortified_glass@0"
            ]
        },
        {
            "x": 0,
            "y": -1,
            "z": 6,
            "elements": [
                "thaumicaugmentation:fortified_glass@0"
            ]
        },
        {
            "x": 5,
            "y": 6,
            "z": 1,
            "elements": [
                "thaumicaugmentation:fortified_glass@0"
            ]
        },
        {
            "x": -5,
            "y": 7,
            "z": 0,
            "elements": [
                "thaumadditions:brass_plated_silverwood@0"
            ]
        },
        {
            "x": -2,
            "y": 5,
            "z": 0,
            "elements": [
                "thaumicaugmentation:fortified_glass@0"
            ]
        },
        {
            "x": -5,
            "y": 2,
            "z": 0,
            "elements": [
                "thaumadditions:brass_plated_silverwood@0"
            ]
        },
        {
            "x": -2,
            "y": 9,
            "z": 6,
            "elements": [
                "thaumicaugmentation:fortified_glass@0"
            ]
        },
        {
            "x": 4,
            "y": 0,
            "z": 0,
            "elements": [
                "thaumcraft:metal_thaumium@0"
            ]
        },
        {
            "x": 3,
            "y": 9,
            "z": 8,
            "elements": [
                "thaumicaugmentation:fortified_glass@0"
            ]
        },
        {
            "x": 5,
            "y": -1,
            "z": 7,
            "elements": [
                "thaumadditions:brass_plated_silverwood@0"
            ]
        },
        {
            "x": 0,
            "y": 9,
            "z": 7,
            "elements": [
                "thaumicaugmentation:fortified_glass@0"
            ]
        },
        {
            "x": -1,
            "y": 9,
            "z": 0,
            "elements": [
                "thaumadditions:brass_plated_silverwood@0"
            ]
        },
        {
            "x": 2,
            "y": -1,
            "z": 4,
            "elements": [
                "thaumicaugmentation:fortified_glass@0"
            ]
        },
        {
            "x": 2,
            "y": 4,
            "z": 0,
            "elements": [
                "thaumicaugmentation:fortified_glass@0"
            ]
        },
        {
            "x": 3,
            "y": -1,
            "z": 0,
            "elements": [
                "thaumadditions:brass_plated_silverwood@0"
            ]
        },
        {
            "x": -4,
            "y": 1,
            "z": 0,
            "elements": [
                "thaumicaugmentation:fortified_glass@0"
            ]
        },
        {
            "x": -4,
            "y": 9,
            "z": 5,
            "elements": [
                "thaumicaugmentation:fortified_glass@0"
            ]
        },
        {
            "x": -1,
            "y": -1,
            "z": 4,
            "elements": [
                "thaumicaugmentation:fortified_glass@0"
            ]
        },
        {
            "x": 1,
            "y": -1,
            "z": 5,
            "elements": [
                "thaumicaugmentation:fortified_glass@0"
            ]
        },
        {
            "x": 1,
            "y": 9,
            "z": 9,
            "elements": [
                "thaumicaugmentation:fortified_glass@0"
            ]
        },
        {
            "x": 2,
            "y": 3,
            "z": 0,
            "elements": [
                "thaumicaugmentation:fortified_glass@0"
            ]
        },
        {
            "x": 0,
            "y": -1,
            "z": 9,
            "elements": [
                "thaumicaugmentation:fortified_glass@0"
            ]
        },
        {
            "x": 3,
            "y": -1,
            "z": 6,
            "elements": [
                "thaumicaugmentation:fortified_glass@0"
            ]
        },
        {
            "x": 5,
            "y": 0,
            "z": 0,
            "elements": [
                "thaumadditions:brass_plated_silverwood@0"
            ]
        },
        {
            "x": 3,
            "y": 9,
            "z": 6,
            "elements": [
                "thaumicaugmentation:fortified_glass@0"
            ]
        },
        {
            "x": 2,
            "y": 2,
            "z": 0,
            "elements": [
                "thaumicaugmentation:fortified_glass@0"
            ]
        },
        {
            "x": -1,
            "y": -1,
            "z": 10,
            "elements": [
                "thaumadditions:brass_plated_silverwood@0"
            ]
        },
        {
            "x": -5,
            "y": 4,
            "z": 0,
            "elements": [
                "thaumadditions:brass_plated_silverwood@0"
            ]
        },
        {
            "x": -5,
            "y": 1,
            "z": 0,
            "elements": [
                "thaumadditions:brass_plated_silverwood@0"
            ]
        },
        {
            "x": 4,
            "y": -1,
            "z": 0,
            "elements": [
                "thaumadditions:brass_plated_silverwood@0"
            ]
        },
        {
            "x": -3,
            "y": 9,
            "z": 5,
            "elements": [
                "thaumicaugmentation:fortified_glass@0"
            ]
        },
        {
            "x": 2,
            "y": 1,
            "z": 0,
            "elements": [
                "thaumicaugmentation:fortified_glass@0"
            ]
        },
        {
            "x": -4,
            "y": -1,
            "z": 4,
            "elements": [
                "thaumicaugmentation:fortified_glass@0"
            ]
        },
        {
            "x": -5,
            "y": 3,
            "z": 0,
            "elements": [
                "thaumadditions:brass_plated_silverwood@0"
            ]
        },
        {
            "x": -3,
            "y": -1,
            "z": 0,
            "elements": [
                "thaumadditions:brass_plated_silverwood@0"
            ]
        },
        {
            "x": -2,
            "y": 0,
            "z": 0,
            "elements": [
                "thaumcraft:metal_thaumium@0"
            ]
        },
        {
            "x": 5,
            "y": -1,
            "z": 3,
            "elements": [
                "thaumadditions:brass_plated_silverwood@0"
            ]
        },
        {
            "x": 2,
            "y": -1,
            "z": 10,
            "elements": [
                "thaumadditions:brass_plated_silverwood@0"
            ]
        },
        {
            "x": 5,
            "y": 9,
            "z": 8,
            "elements": [
                "thaumadditions:brass_plated_silverwood@0"
            ]
        },
        {
            "x": -3,
            "y": 4,
            "z": 10,
            "elements": [
                "thaumicaugmentation:fortified_glass@0"
            ]
        },
        {
            "x": 0,
            "y": 9,
            "z": 6,
            "elements": [
                "thaumicaugmentation:fortified_glass@0"
            ]
        },
        {
            "x": 2,
            "y": 7,
            "z": 0,
            "elements": [
                "thaumicaugmentation:fortified_glass@0"
            ]
        },
        {
            "x": -3,
            "y": 5,
            "z": 10,
            "elements": [
                "thaumicaugmentation:fortified_glass@0"
            ]
        },
        {
            "x": 5,
            "y": 2,
            "z": 0,
            "elements": [
                "thaumadditions:brass_plated_silverwood@0"
            ]
        },
        {
            "x": -5,
            "y": -1,
            "z": 5,
            "elements": [
                "thaumadditions:brass_plated_silverwood@0"
            ]
        },
        {
            "x": 0,
            "y": 1,
            "z": 10,
            "elements": [
                "thaumicaugmentation:fortified_glass@0"
            ]
        },
        {
            "x": -3,
            "y": 3,
            "z": 10,
            "elements": [
                "thaumicaugmentation:fortified_glass@0"
            ]
        },
        {
            "x": -5,
            "y": 7,
            "z": 9,
            "elements": [
                "thaumicaugmentation:fortified_glass@0"
            ]
        },
        {
            "x": -1,
            "y": 6,
            "z": 0,
            "elements": [
                "thaumicaugmentation:fortified_glass@0"
            ]
        },
        {
            "x": 0,
            "y": 0,
            "z": 10,
            "elements": [
                "modularmachinery:blockaspectproviderinput"
            ]
        },
        {
            "x": -3,
            "y": 2,
            "z": 10,
            "elements": [
                "thaumicaugmentation:fortified_glass@0"
            ]
        },
        {
            "x": -5,
            "y": 8,
            "z": 9,
            "elements": [
                "thaumcraft:metal_thaumium@0"
            ]
        },
        {
            "x": 2,
            "y": 8,
            "z": 0,
            "elements": [
                "thaumcraft:metal_thaumium@0"
            ]
        },
        {
            "x": 5,
            "y": 1,
            "z": 0,
            "elements": [
                "thaumadditions:brass_plated_silverwood@0"
            ]
        },
        {
            "x": 0,
            "y": 4,
            "z": 10,
            "elements": [
                "thaumicaugmentation:fortified_glass@0"
            ]
        },
        {
            "x": -3,
            "y": 6,
            "z": 10,
            "elements": [
                "thaumicaugmentation:fortified_glass@0"
            ]
        },
        {
            "x": -5,
            "y": 9,
            "z": 9,
            "elements": [
                "thaumadditions:brass_plated_silverwood@0"
            ]
        },
        {
            "x": -5,
            "y": 0,
            "z": 0,
            "elements": [
                "thaumadditions:brass_plated_silverwood@0"
            ]
        },
        {
            "x": -1,
            "y": 5,
            "z": 0,
            "elements": [
                "thaumicaugmentation:fortified_glass@0"
            ]
        },
        {
            "x": 5,
            "y": -1,
            "z": 6,
            "elements": [
                "thaumadditions:brass_plated_silverwood@0"
            ]
        },
        {
            "x": -3,
            "y": 1,
            "z": 10,
            "elements": [
                "thaumicaugmentation:fortified_glass@0"
            ]
        },
        {
            "x": -1,
            "y": 7,
            "z": 0,
            "elements": [
                "thaumicaugmentation:fortified_glass@0"
            ]
        },
        {
            "x": 2,
            "y": 5,
            "z": 0,
            "elements": [
                "thaumicaugmentation:fortified_glass@0"
            ]
        },
        {
            "x": -5,
            "y": 5,
            "z": 9,
            "elements": [
                "thaumicaugmentation:fortified_glass@0"
            ]
        },
        {
            "x": 2,
            "y": -1,
            "z": 7,
            "elements": [
                "thaumicaugmentation:fortified_glass@0"
            ]
        },
        {
            "x": 1,
            "y": 9,
            "z": 6,
            "elements": [
                "thaumicaugmentation:fortified_glass@0"
            ]
        },
        {
            "x": 5,
            "y": 8,
            "z": 1,
            "elements": [
                "thaumcraft:metal_thaumium@0"
            ]
        },
        {
            "x": -4,
            "y": 9,
            "z": 0,
            "elements": [
                "thaumadditions:brass_plated_silverwood@0"
            ]
        },
        {
            "x": 0,
            "y": 3,
            "z": 10,
            "elements": [
                "thaumicaugmentation:fortified_glass@0"
            ]
        },
        {
            "x": -3,
            "y": 7,
            "z": 10,
            "elements": [
                "thaumicaugmentation:fortified_glass@0"
            ]
        },
        {
            "x": -2,
            "y": -1,
            "z": 5,
            "elements": [
                "thaumicaugmentation:fortified_glass@0"
            ]
        },
        {
            "x": 5,
            "y": 4,
            "z": 0,
            "elements": [
                "thaumadditions:brass_plated_silverwood@0"
            ]
        },
        {
            "x": -3,
            "y": 8,
            "z": 10,
            "elements": [
                "thaumcraft:metal_thaumium@0"
            ]
        },
        {
            "x": 2,
            "y": 6,
            "z": 0,
            "elements": [
                "thaumicaugmentation:fortified_glass@0"
            ]
        },
        {
            "x": -4,
            "y": -1,
            "z": 1,
            "elements": [
                "thaumicaugmentation:fortified_glass@0"
            ]
        },
        {
            "x": 5,
            "y": 9,
            "z": 1,
            "elements": [
                "thaumadditions:brass_plated_silverwood@0"
            ]
        },
        {
            "x": -3,
            "y": 0,
            "z": 10,
            "elements": [
                "thaumcraft:metal_thaumium@0"
            ]
        },
        {
            "x": -1,
            "y": 8,
            "z": 0,
            "elements": [
                "thaumcraft:metal_thaumium@0"
            ]
        },
        {
            "x": -5,
            "y": 8,
            "z": 4,
            "elements": [
                "thaumcraft:metal_thaumium@0"
            ]
        },
        {
            "x": 4,
            "y": 7,
            "z": 0,
            "elements": [
                "thaumicaugmentation:fortified_glass@0"
            ]
        },
        {
            "x": 5,
            "y": 3,
            "z": 0,
            "elements": [
                "thaumadditions:brass_plated_silverwood@0"
            ]
        },
        {
            "x": -5,
            "y": 6,
            "z": 9,
            "elements": [
                "thaumicaugmentation:fortified_glass@0"
            ]
        },
        {
            "x": -3,
            "y": 9,
            "z": 4,
            "elements": [
                "thaumicaugmentation:fortified_glass@0"
            ]
        },
        {
            "x": 5,
            "y": 1,
            "z": 5,
            "elements": [
                "thaumicaugmentation:fortified_glass@0"
            ]
        },
        {
            "x": 0,
            "y": 2,
            "z": 10,
            "elements": [
                "thaumicaugmentation:fortified_glass@0"
            ]
        },
        {
            "x": -3,
            "y": 9,
            "z": 10,
            "elements": [
                "thaumadditions:brass_plated_silverwood@0"
            ]
        },
        {
            "x": -5,
            "y": 8,
            "z": 3,
            "elements": [
                "thaumcraft:metal_thaumium@0"
            ]
        },
        {
            "x": 0,
            "y": 7,
            "z": 10,
            "elements": [
                "thaumicaugmentation:fortified_glass@0"
            ]
        },
        {
            "x": -5,
            "y": 3,
            "z": 9,
            "elements": [
                "thaumicaugmentation:fortified_glass@0"
            ]
        },
        {
            "x": 2,
            "y": -1,
            "z": 8,
            "elements": [
                "thaumicaugmentation:fortified_glass@0"
            ]
        },
        {
            "x": 4,
            "y": 9,
            "z": 7,
            "elements": [
                "thaumicaugmentation:fortified_glass@0"
            ]
        },
        {
            "x": 3,
            "y": -1,
            "z": 3,
            "elements": [
                "thaumicaugmentation:fortified_glass@0"
            ]
        },
        {
            "x": 5,
            "y": 8,
            "z": 2,
            "elements": [
                "thaumcraft:metal_thaumium@0"
            ]
        },
        {
            "x": 5,
            "y": 2,
            "z": 5,
            "elements": [
                "thaumicaugmentation:fortified_glass@0"
            ]
        },
        {
            "x": 5,
            "y": 7,
            "z": 7,
            "elements": [
                "thaumicaugmentation:fortified_glass@0"
            ]
        },
        {
            "x": 0,
            "y": 9,
            "z": 5,
            "elements": [
                "thaumicaugmentation:fortified_glass@0"
            ]
        },
        {
            "x": 5,
            "y": 0,
            "z": 5,
            "elements": [
                "modularmachinery:blockinputbus"
            ]
        },
        {
            "x": -4,
            "y": -1,
            "z": 9,
            "elements": [
                "thaumicaugmentation:fortified_glass@0"
            ]
        },
        {
            "x": 4,
            "y": -1,
            "z": 2,
            "elements": [
                "thaumicaugmentation:fortified_glass@0"
            ]
        },
        {
            "x": 0,
            "y": 8,
            "z": 10,
            "elements": [
                "modularmachinery:blockimpetusproviderinput@0"
            ]
        },
        {
            "x": 5,
            "y": 9,
            "z": 2,
            "elements": [
                "thaumadditions:brass_plated_silverwood@0"
            ]
        },
        {
            "x": -5,
            "y": -1,
            "z": 4,
            "elements": [
                "thaumadditions:brass_plated_silverwood@0"
            ]
        },
        {
            "x": -5,
            "y": 7,
            "z": 4,
            "elements": [
                "thaumicaugmentation:fortified_glass@0"
            ]
        },
        {
            "x": -5,
            "y": 7,
            "z": 3,
            "elements": [
                "thaumicaugmentation:fortified_glass@0"
            ]
        },
        {
            "x": -5,
            "y": 4,
            "z": 9,
            "elements": [
                "thaumicaugmentation:fortified_glass@0"
            ]
        },
        {
            "x": 3,
            "y": 2,
            "z": 10,
            "elements": [
                "thaumicaugmentation:fortified_glass@0"
            ]
        },
        {
            "x": 4,
            "y": 8,
            "z": 0,
            "elements": [
                "thaumcraft:metal_thaumium@0"
            ]
        },
        {
            "x": 5,
            "y": -1,
            "z": 5,
            "elements": [
                "thaumadditions:brass_plated_silverwood@0"
            ]
        },
        {
            "x": 5,
            "y": 6,
            "z": 7,
            "elements": [
                "thaumicaugmentation:fortified_glass@0"
            ]
        },
        {
            "x": -5,
            "y": 3,
            "z": 3,
            "elements": [
                "thaumicaugmentation:fortified_glass@0"
            ]
        },
        {
            "x": 3,
            "y": -1,
            "z": 10,
            "elements": [
                "thaumadditions:brass_plated_silverwood@0"
            ]
        },
        {
            "x": 4,
            "y": 5,
            "z": 0,
            "elements": [
                "thaumicaugmentation:fortified_glass@0"
            ]
        },
        {
            "x": 5,
            "y": 9,
            "z": 7,
            "elements": [
                "thaumadditions:brass_plated_silverwood@0"
            ]
        },
        {
            "x": -2,
            "y": 9,
            "z": 10,
            "elements": [
                "thaumadditions:brass_plated_silverwood@0"
            ]
        },
        {
            "x": 5,
            "y": -1,
            "z": 8,
            "elements": [
                "thaumadditions:brass_plated_silverwood@0"
            ]
        },
        {
            "x": -5,
            "y": 2,
            "z": 9,
            "elements": [
                "thaumicaugmentation:fortified_glass@0"
            ]
        },
        {
            "x": 0,
            "y": 5,
            "z": 10,
            "elements": [
                "thaumicaugmentation:fortified_glass@0"
            ]
        },
        {
            "x": 0,
            "y": -1,
            "z": 3,
            "elements": [
                "thaumicaugmentation:fortified_glass@0"
            ]
        },
        {
            "x": 3,
            "y": 1,
            "z": 10,
            "elements": [
                "thaumicaugmentation:fortified_glass@0"
            ]
        },
        {
            "x": -5,
            "y": 9,
            "z": 3,
            "elements": [
                "thaumadditions:brass_plated_silverwood@0"
            ]
        },
        {
            "x": -5,
            "y": 9,
            "z": 4,
            "elements": [
                "thaumadditions:brass_plated_silverwood@0"
            ]
        },
        {
            "x": -5,
            "y": -1,
            "z": 9,
            "elements": [
                "thaumadditions:brass_plated_silverwood@0"
            ]
        },
        {
            "x": 4,
            "y": 6,
            "z": 0,
            "elements": [
                "thaumicaugmentation:fortified_glass@0"
            ]
        },
        {
            "x": 5,
            "y": 8,
            "z": 7,
            "elements": [
                "thaumcraft:metal_thaumium@0"
            ]
        },
        {
            "x": 1,
            "y": 4,
            "z": 10,
            "elements": [
                "thaumicaugmentation:fortified_glass@0"
            ]
        },
        {
            "x": 3,
            "y": 0,
            "z": 10,
            "elements": [
                "thaumcraft:metal_thaumium@0"
            ]
        },
        {
            "x": -5,
            "y": 1,
            "z": 9,
            "elements": [
                "thaumicaugmentation:fortified_glass@0"
            ]
        },
        {
            "x": 0,
            "y": 6,
            "z": 10,
            "elements": [
                "thaumicaugmentation:fortified_glass@0"
            ]
        },
        {
            "x": 4,
            "y": -1,
            "z": 5,
            "elements": [
                "thaumicaugmentation:fortified_glass@0"
            ]
        },
        {
            "x": -5,
            "y": 0,
            "z": 9,
            "elements": [
                "thaumcraft:metal_thaumium@0"
            ]
        },
        {
            "x": -5,
            "y": 9,
            "z": 10,
            "elements": [
                "thaumadditions:brass_plated_silverwood@0"
            ]
        },
        {
            "x": 5,
            "y": 3,
            "z": 2,
            "elements": [
                "thaumicaugmentation:fortified_glass@0"
            ]
        },
        {
            "x": 5,
            "y": 4,
            "z": 2,
            "elements": [
                "thaumicaugmentation:fortified_glass@0"
            ]
        },
        {
            "x": 1,
            "y": 5,
            "z": 10,
            "elements": [
                "thaumicaugmentation:fortified_glass@0"
            ]
        },
        {
            "x": -5,
            "y": 3,
            "z": 4,
            "elements": [
                "thaumicaugmentation:fortified_glass@0"
            ]
        },
        {
            "x": -2,
            "y": 7,
            "z": 10,
            "elements": [
                "thaumicaugmentation:fortified_glass@0"
            ]
        },
        {
            "x": 2,
            "y": 9,
            "z": 5,
            "elements": [
                "thaumicaugmentation:fortified_glass@0"
            ]
        },
        {
            "x": 1,
            "y": 3,
            "z": 10,
            "elements": [
                "thaumicaugmentation:fortified_glass@0"
            ]
        },
        {
            "x": -5,
            "y": 1,
            "z": 3,
            "elements": [
                "thaumicaugmentation:fortified_glass@0"
            ]
        },
        {
            "x": -2,
            "y": 9,
            "z": 3,
            "elements": [
                "thaumicaugmentation:fortified_glass@0"
            ]
        },
        {
            "x": 4,
            "y": 1,
            "z": 10,
            "elements": [
                "thaumicaugmentation:fortified_glass@0"
            ]
        },
        {
            "x": 4,
            "y": 4,
            "z": 0,
            "elements": [
                "thaumicaugmentation:fortified_glass@0"
            ]
        },
        {
            "x": -1,
            "y": 9,
            "z": 2,
            "elements": [
                "thaumicaugmentation:fortified_glass@0"
            ]
        },
        {
            "x": -5,
            "y": 4,
            "z": 4,
            "elements": [
                "thaumicaugmentation:fortified_glass@0"
            ]
        },
        {
            "x": 5,
            "y": 5,
            "z": 5,
            "elements": [
                "thaumicaugmentation:fortified_glass@0"
            ]
        },
        {
            "x": -2,
            "y": 8,
            "z": 10,
            "elements": [
                "thaumcraft:metal_thaumium@0"
            ]
        },
        {
            "x": 4,
            "y": 3,
            "z": 10,
            "elements": [
                "thaumicaugmentation:fortified_glass@0"
            ]
        },
        {
            "x": -3,
            "y": -1,
            "z": 4,
            "elements": [
                "thaumicaugmentation:fortified_glass@0"
            ]
        },
        {
            "x": 5,
            "y": 2,
            "z": 2,
            "elements": [
                "thaumicaugmentation:fortified_glass@0"
            ]
        },
        {
            "x": -5,
            "y": 2,
            "z": 3,
            "elements": [
                "thaumicaugmentation:fortified_glass@0"
            ]
        },
        {
            "x": 5,
            "y": 5,
            "z": 2,
            "elements": [
                "thaumicaugmentation:fortified_glass@0"
            ]
        },
        {
            "x": 1,
            "y": 6,
            "z": 10,
            "elements": [
                "thaumicaugmentation:fortified_glass@0"
            ]
        },
        {
            "x": 1,
            "y": 2,
            "z": 10,
            "elements": [
                "thaumicaugmentation:fortified_glass@0"
            ]
        },
        {
            "x": 4,
            "y": 9,
            "z": 6,
            "elements": [
                "thaumicaugmentation:fortified_glass@0"
            ]
        },
        {
            "x": 4,
            "y": 3,
            "z": 0,
            "elements": [
                "thaumicaugmentation:fortified_glass@0"
            ]
        },
        {
            "x": 4,
            "y": 0,
            "z": 10,
            "elements": [
                "thaumcraft:metal_thaumium@0"
            ]
        },
        {
            "x": 4,
            "y": 4,
            "z": 10,
            "elements": [
                "thaumicaugmentation:fortified_glass@0"
            ]
        },
        {
            "x": -5,
            "y": 5,
            "z": 4,
            "elements": [
                "thaumicaugmentation:fortified_glass@0"
            ]
        },
        {
            "x": 1,
            "y": 7,
            "z": 10,
            "elements": [
                "thaumicaugmentation:fortified_glass@0"
            ]
        },
        {
            "x": -1,
            "y": -1,
            "z": 8,
            "elements": [
                "thaumicaugmentation:fortified_glass@0"
            ]
        },
        {
            "x": 0,
            "y": 9,
            "z": 10,
            "elements": [
                "thaumadditions:brass_plated_silverwood@0"
            ]
        },
        {
            "x": 5,
            "y": 1,
            "z": 2,
            "elements": [
                "thaumicaugmentation:fortified_glass@0"
            ]
        },
        {
            "x": 5,
            "y": 4,
            "z": 5,
            "elements": [
                "thaumicaugmentation:fortified_glass@0"
            ]
        },
        {
            "x": 5,
            "y": 6,
            "z": 2,
            "elements": [
                "thaumicaugmentation:fortified_glass@0"
            ]
        },
        {
            "x": 4,
            "y": 2,
            "z": 0,
            "elements": [
                "thaumicaugmentation:fortified_glass@0"
            ]
        },
        {
            "x": -2,
            "y": 5,
            "z": 10,
            "elements": [
                "thaumicaugmentation:fortified_glass@0"
            ]
        },
        {
            "x": -1,
            "y": 9,
            "z": 5,
            "elements": [
                "thaumicaugmentation:fortified_glass@0"
            ]
        },
        {
            "x": 1,
            "y": 1,
            "z": 10,
            "elements": [
                "thaumicaugmentation:fortified_glass@0"
            ]
        },
        {
            "x": 1,
            "y": 8,
            "z": 10,
            "elements": [
                "thaumcraft:metal_thaumium@0"
            ]
        },
        {
            "x": 5,
            "y": 7,
            "z": 2,
            "elements": [
                "thaumicaugmentation:fortified_glass@0"
            ]
        },
        {
            "x": -3,
            "y": -1,
            "z": 9,
            "elements": [
                "thaumicaugmentation:fortified_glass@0"
            ]
        },
        {
            "x": -2,
            "y": -1,
            "z": 4,
            "elements": [
                "thaumicaugmentation:fortified_glass@0"
            ]
        },
        {
            "x": 1,
            "y": 0,
            "z": 10,
            "elements": [
                "thaumcraft:metal_thaumium@0"
            ]
        },
        {
            "x": -5,
            "y": -1,
            "z": 0,
            "elements": [
                "thaumadditions:brass_plated_silverwood@0"
            ]
        },
        {
            "x": -5,
            "y": 6,
            "z": 4,
            "elements": [
                "thaumicaugmentation:fortified_glass@0"
            ]
        },
        {
            "x": 5,
            "y": 3,
            "z": 5,
            "elements": [
                "thaumicaugmentation:fortified_glass@0"
            ]
        },
        {
            "x": 4,
            "y": 1,
            "z": 0,
            "elements": [
                "thaumicaugmentation:fortified_glass@0"
            ]
        },
        {
            "x": -5,
            "y": 0,
            "z": 3,
            "elements": [
                "thaumcraft:metal_thaumium@0"
            ]
        },
        {
            "x": 2,
            "y": -1,
            "z": 5,
            "elements": [
                "thaumicaugmentation:fortified_glass@0"
            ]
        },
        {
            "x": 5,
            "y": 0,
            "z": 2,
            "elements": [
                "thaumcraft:metal_thaumium@0"
            ]
        },
        {
            "x": 4,
            "y": 2,
            "z": 10,
            "elements": [
                "thaumicaugmentation:fortified_glass@0"
            ]
        },
        {
            "x": -4,
            "y": 0,
            "z": 0,
            "elements": [
                "thaumcraft:metal_thaumium@0"
            ]
        },
        {
            "x": 5,
            "y": 6,
            "z": 5,
            "elements": [
                "thaumicaugmentation:fortified_glass@0"
            ]
        },
        {
            "x": -4,
            "y": 9,
            "z": 2,
            "elements": [
                "thaumicaugmentation:fortified_glass@0"
            ]
        },
        {
            "x": -2,
            "y": 6,
            "z": 10,
            "elements": [
                "thaumicaugmentation:fortified_glass@0"
            ]
        },
        {
            "x": -2,
            "y": 1,
            "z": 10,
            "elements": [
                "thaumicaugmentation:fortified_glass@0"
            ]
        },
        {
            "x": 0,
            "y": -1,
            "z": 10,
            "elements": [
                "thaumadditions:brass_plated_silverwood@0"
            ]
        },
        {
            "x": -1,
            "y": -1,
            "z": 3,
            "elements": [
                "thaumicaugmentation:fortified_glass@0"
            ]
        },
        {
            "x": 5,
            "y": 7,
            "z": 5,
            "elements": [
                "thaumicaugmentation:fortified_glass@0"
            ]
        },
        {
            "x": 1,
            "y": 6,
            "z": 0,
            "elements": [
                "thaumicaugmentation:fortified_glass@0"
            ]
        },
        {
            "x": -4,
            "y": 9,
            "z": 3,
            "elements": [
                "thaumicaugmentation:fortified_glass@0"
            ]
        },
        {
            "x": -4,
            "y": 9,
            "z": 4,
            "elements": [
                "thaumicaugmentation:fortified_glass@0"
            ]
        },
        {
            "x": -2,
            "y": 0,
            "z": 10,
            "elements": [
                "thaumcraft:metal_thaumium@0"
            ]
        },
        {
            "x": 0,
            "y": 9,
            "z": 8,
            "elements": [
                "thaumicaugmentation:fortified_glass@0"
            ]
        },
        {
            "x": 5,
            "y": 8,
            "z": 5,
            "elements": [
                "thaumcraft:metal_thaumium@0"
            ]
        },
        {
            "x": -5,
            "y": 6,
            "z": 10,
            "elements": [
                "thaumadditions:brass_plated_silverwood@0"
            ]
        },
        {
            "x": 1,
            "y": 5,
            "z": 0,
            "elements": [
                "thaumicaugmentation:fortified_glass@0"
            ]
        },
        {
            "x": 5,
            "y": 9,
            "z": 5,
            "elements": [
                "thaumadditions:brass_plated_silverwood@0"
            ]
        },
        {
            "x": -2,
            "y": 4,
            "z": 10,
            "elements": [
                "thaumicaugmentation:fortified_glass@0"
            ]
        },
        {
            "x": -2,
            "y": 9,
            "z": 0,
            "elements": [
                "thaumadditions:brass_plated_silverwood@0"
            ]
        },
        {
            "x": 1,
            "y": 7,
            "z": 0,
            "elements": [
                "thaumicaugmentation:fortified_glass@0"
            ]
        },
        {
            "x": -5,
            "y": 1,
            "z": 4,
            "elements": [
                "thaumicaugmentation:fortified_glass@0"
            ]
        },
        {
            "x": -2,
            "y": 3,
            "z": 10,
            "elements": [
                "thaumicaugmentation:fortified_glass@0"
            ]
        },
        {
            "x": -5,
            "y": 7,
            "z": 10,
            "elements": [
                "thaumadditions:brass_plated_silverwood@0"
            ]
        },
        {
            "x": -4,
            "y": -1,
            "z": 3,
            "elements": [
                "thaumicaugmentation:fortified_glass@0"
            ]
        },
        {
            "x": 1,
            "y": 8,
            "z": 0,
            "elements": [
                "thaumcraft:metal_thaumium@0"
            ]
        },
        {
            "x": 3,
            "y": 9,
            "z": 1,
            "elements": [
                "thaumicaugmentation:fortified_glass@0"
            ]
        },
        {
            "x": 2,
            "y": 9,
            "z": 2,
            "elements": [
                "thaumicaugmentation:fortified_glass@0"
            ]
        },
        {
            "x": -5,
            "y": 2,
            "z": 4,
            "elements": [
                "thaumicaugmentation:fortified_glass@0"
            ]
        },
        {
            "x": -5,
            "y": 8,
            "z": 10,
            "elements": [
                "thaumadditions:brass_plated_silverwood@0"
            ]
        },
        {
            "x": -2,
            "y": 2,
            "z": 10,
            "elements": [
                "thaumicaugmentation:fortified_glass@0"
            ]
        },
        {
            "x": -1,
            "y": 9,
            "z": 4,
            "elements": [
                "thaumicaugmentation:fortified_glass@0"
            ]
        },
        {
            "x": -3,
            "y": 9,
            "z": 8,
            "elements": [
                "thaumicaugmentation:fortified_glass@0"
            ]
        },
        {
            "x": 0,
            "y": -1,
            "z": 4,
            "elements": [
                "thaumicaugmentation:fortified_glass@0"
            ]
        },
        {
            "x": 1,
            "y": 9,
            "z": 0,
            "elements": [
                "thaumadditions:brass_plated_silverwood@0"
            ]
        },
        {
            "x": -3,
            "y": -1,
            "z": 3,
            "elements": [
                "thaumicaugmentation:fortified_glass@0"
            ]
        },
        {
            "x": -5,
            "y": 4,
            "z": 3,
            "elements": [
                "thaumicaugmentation:fortified_glass@0"
            ]
        },
        {
            "x": -2,
            "y": -1,
            "z": 9,
            "elements": [
                "thaumicaugmentation:fortified_glass@0"
            ]
        },
        {
            "x": -3,
            "y": -1,
            "z": 10,
            "elements": [
                "thaumadditions:brass_plated_silverwood@0"
            ]
        },
        {
            "x": -5,
            "y": 0,
            "z": 4,
            "elements": [
                "thaumcraft:metal_thaumium@0"
            ]
        },
        {
            "x": 1,
            "y": -1,
            "z": 4,
            "elements": [
                "thaumicaugmentation:fortified_glass@0"
            ]
        },
        {
            "x": -2,
            "y": -1,
            "z": 3,
            "elements": [
                "thaumicaugmentation:fortified_glass@0"
            ]
        },
        {
            "x": -5,
            "y": 6,
            "z": 3,
            "elements": [
                "thaumicaugmentation:fortified_glass@0"
            ]
        },
        {
            "x": 4,
            "y": 9,
            "z": 0,
            "elements": [
                "thaumadditions:brass_plated_silverwood@0"
            ]
        },
        {
            "x": -1,
            "y": 9,
            "z": 8,
            "elements": [
                "thaumicaugmentation:fortified_glass@0"
            ]
        },
        {
            "x": -5,
            "y": 5,
            "z": 3,
            "elements": [
                "thaumicaugmentation:fortified_glass@0"
            ]
        },
        {
            "x": 1,
            "y": -1,
            "z": 9,
            "elements": [
                "thaumicaugmentation:fortified_glass@0"
            ]
        },
        {
            "x": 1,
            "y": -1,
            "z": 7,
            "elements": [
                "thaumicaugmentation:fortified_glass@0"
            ]
        },
        {
            "x": 2,
            "y": 9,
            "z": 6,
            "elements": [
                "thaumicaugmentation:fortified_glass@0"
            ]
        },
        {
            "x": 5,
            "y": 3,
            "z": 6,
            "elements": [
                "thaumicaugmentation:fortified_glass@0"
            ]
        },
        {
            "x": -5,
            "y": -1,
            "z": 3,
            "elements": [
                "thaumadditions:brass_plated_silverwood@0"
            ]
        },
        {
            "x": -4,
            "y": 9,
            "z": 7,
            "elements": [
                "thaumicaugmentation:fortified_glass@0"
            ]
        },
        {
            "x": 5,
            "y": 9,
            "z": 10,
            "elements": [
                "thaumadditions:brass_plated_silverwood@0"
            ]
        },
        {
            "x": -3,
            "y": 9,
            "z": 9,
            "elements": [
                "thaumicaugmentation:fortified_glass@0"
            ]
        },
        {
            "x": 4,
            "y": 9,
            "z": 1,
            "elements": [
                "thaumicaugmentation:fortified_glass@0"
            ]
        },
        {
            "x": 5,
            "y": 0,
            "z": 9,
            "elements": [
                "thaumcraft:metal_thaumium@0"
            ]
        },
        {
            "x": -4,
            "y": -1,
            "z": 2,
            "elements": [
                "thaumicaugmentation:fortified_glass@0"
            ]
        },
        {
            "x": 4,
            "y": -1,
            "z": 9,
            "elements": [
                "thaumicaugmentation:fortified_glass@0"
            ]
        },
        {
            "x": -4,
            "y": 9,
            "z": 8,
            "elements": [
                "thaumicaugmentation:fortified_glass@0"
            ]
        },
        {
            "x": -3,
            "y": 9,
            "z": 2,
            "elements": [
                "thaumicaugmentation:fortified_glass@0"
            ]
        },
        {
            "x": -1,
            "y": 9,
            "z": 6,
            "elements": [
                "thaumicaugmentation:fortified_glass@0"
            ]
        },
        {
            "x": 5,
            "y": 2,
            "z": 6,
            "elements": [
                "thaumicaugmentation:fortified_glass@0"
            ]
        },
        {
            "x": 3,
            "y": -1,
            "z": 4,
            "elements": [
                "thaumicaugmentation:fortified_glass@0"
            ]
        },
        {
            "x": 5,
            "y": 5,
            "z": 6,
            "elements": [
                "thaumicaugmentation:fortified_glass@0"
            ]
        },
        {
            "x": -5,
            "y": 0,
            "z": 8,
            "elements": [
                "thaumcraft:metal_thaumium@0"
            ]
        },
        {
            "x": -2,
            "y": 9,
            "z": 2,
            "elements": [
                "thaumicaugmentation:fortified_glass@0"
            ]
        },
        {
            "x": -5,
            "y": -1,
            "z": 2,
            "elements": [
                "thaumadditions:brass_plated_silverwood@0"
            ]
        },
        {
            "x": 5,
            "y": 4,
            "z": 6,
            "elements": [
                "thaumicaugmentation:fortified_glass@0"
            ]
        },
        {
            "x": 5,
            "y": 7,
            "z": 6,
            "elements": [
                "thaumicaugmentation:fortified_glass@0"
            ]
        },
        {
            "x": 0,
            "y": -1,
            "z": 8,
            "elements": [
                "thaumicaugmentation:fortified_glass@0"
            ]
        },
        {
            "x": -4,
            "y": 9,
            "z": 6,
            "elements": [
                "thaumicaugmentation:fortified_glass@0"
            ]
        },
        {
            "x": 1,
            "y": -1,
            "z": 3,
            "elements": [
                "thaumicaugmentation:fortified_glass@0"
            ]
        },
        {
            "x": 4,
            "y": -1,
            "z": 4,
            "elements": [
                "thaumicaugmentation:fortified_glass@0"
            ]
        },
        {
            "x": -5,
            "y": -1,
            "z": 7,
            "elements": [
                "thaumadditions:brass_plated_silverwood@0"
            ]
        },
        {
            "x": 2,
            "y": -1,
            "z": 2,
            "elements": [
                "thaumicaugmentation:fortified_glass@0"
            ]
        },
        {
            "x": 5,
            "y": 3,
            "z": 9,
            "elements": [
                "thaumicaugmentation:fortified_glass@0"
            ]
        },
        {
            "x": 5,
            "y": 6,
            "z": 6,
            "elements": [
                "thaumicaugmentation:fortified_glass@0"
            ]
        },
        {
            "x": 2,
            "y": -1,
            "z": 9,
            "elements": [
                "thaumicaugmentation:fortified_glass@0"
            ]
        },
        {
            "x": 3,
            "y": 9,
            "z": 10,
            "elements": [
                "thaumadditions:brass_plated_silverwood@0"
            ]
        },
        {
            "x": 5,
            "y": 4,
            "z": 9,
            "elements": [
                "thaumicaugmentation:fortified_glass@0"
            ]
        },
        {
            "x": 1,
            "y": -1,
            "z": 6,
            "elements": [
                "thaumicaugmentation:fortified_glass@0"
            ]
        },
        {
            "x": 5,
            "y": 0,
            "z": 4,
            "elements": [
                "thaumcraft:metal_thaumium@0"
            ]
        },
        {
            "x": -1,
            "y": 9,
            "z": 9,
            "elements": [
                "thaumicaugmentation:fortified_glass@0"
            ]
        },
        {
            "x": 5,
            "y": 1,
            "z": 4,
            "elements": [
                "thaumicaugmentation:fortified_glass@0"
            ]
        },
        {
            "x": 5,
            "y": 1,
            "z": 9,
            "elements": [
                "thaumicaugmentation:fortified_glass@0"
            ]
        },
        {
            "x": 5,
            "y": -1,
            "z": 2,
            "elements": [
                "thaumadditions:brass_plated_silverwood@0"
            ]
        },
        {
            "x": -2,
            "y": -1,
            "z": 7,
            "elements": [
                "thaumicaugmentation:fortified_glass@0"
            ]
        },
        {
            "x": 1,
            "y": 9,
            "z": 1,
            "elements": [
                "thaumicaugmentation:fortified_glass@0"
            ]
        },
        {
            "x": 5,
            "y": 2,
            "z": 9,
            "elements": [
                "thaumicaugmentation:fortified_glass@0"
            ]
        },
        {
            "x": 5,
            "y": 8,
            "z": 6,
            "elements": [
                "thaumcraft:metal_thaumium@0"
            ]
        },
        {
            "x": 5,
            "y": -1,
            "z": 9,
            "elements": [
                "thaumadditions:brass_plated_silverwood@0"
            ]
        },
        {
            "x": 5,
            "y": 2,
            "z": 4,
            "elements": [
                "thaumicaugmentation:fortified_glass@0"
            ]
        },
        {
            "x": 1,
            "y": 9,
            "z": 4,
            "elements": [
                "thaumicaugmentation:fortified_glass@0"
            ]
        },
        {
            "x": -4,
            "y": 9,
            "z": 9,
            "elements": [
                "thaumicaugmentation:fortified_glass@0"
            ]
        },
        {
            "x": 5,
            "y": 9,
            "z": 6,
            "elements": [
                "thaumadditions:brass_plated_silverwood@0"
            ]
        },
        {
            "x": -2,
            "y": -1,
            "z": 8,
            "elements": [
                "thaumicaugmentation:fortified_glass@0"
            ]
        },
        {
            "x": -5,
            "y": 8,
            "z": 8,
            "elements": [
                "thaumcraft:metal_thaumium@0"
            ]
        },
        {
            "x": 1,
            "y": 9,
            "z": 10,
            "elements": [
                "thaumadditions:brass_plated_silverwood@0"
            ]
        },
        {
            "x": 5,
            "y": 4,
            "z": 3,
            "elements": [
                "thaumicaugmentation:fortified_glass@0"
            ]
        },
        {
            "x": -5,
            "y": 5,
            "z": 1,
            "elements": [
                "thaumicaugmentation:fortified_glass@0"
            ]
        },
        {
            "x": 4,
            "y": 7,
            "z": 10,
            "elements": [
                "thaumicaugmentation:fortified_glass@0"
            ]
        },
        {
            "x": 4,
            "y": 9,
            "z": 3,
            "elements": [
                "thaumicaugmentation:fortified_glass@0"
            ]
        },
        {
            "x": -5,
            "y": 4,
            "z": 1,
            "elements": [
                "thaumicaugmentation:fortified_glass@0"
            ]
        },
        {
            "x": 3,
            "y": 5,
            "z": 10,
            "elements": [
                "thaumicaugmentation:fortified_glass@0"
            ]
        },
        {
            "x": 0,
            "y": -1,
            "z": 2,
            "elements": [
                "thaumicaugmentation:fortified_glass@0"
            ]
        },
        {
            "x": 3,
            "y": 6,
            "z": 10,
            "elements": [
                "thaumicaugmentation:fortified_glass@0"
            ]
        },
        {
            "x": 4,
            "y": 8,
            "z": 10,
            "elements": [
                "thaumcraft:metal_thaumium@0"
            ]
        },
        {
            "x": -5,
            "y": 7,
            "z": 8,
            "elements": [
                "thaumicaugmentation:fortified_glass@0"
            ]
        },
        {
            "x": 4,
            "y": 9,
            "z": 4,
            "elements": [
                "thaumicaugmentation:fortified_glass@0"
            ]
        },
        {
            "x": 5,
            "y": 3,
            "z": 3,
            "elements": [
                "thaumicaugmentation:fortified_glass@0"
            ]
        },
        {
            "x": -5,
            "y": -1,
            "z": 8,
            "elements": [
                "thaumadditions:brass_plated_silverwood@0"
            ]
        },
        {
            "x": 5,
            "y": 6,
            "z": 3,
            "elements": [
                "thaumicaugmentation:fortified_glass@0"
            ]
        },
        {
            "x": -5,
            "y": 7,
            "z": 1,
            "elements": [
                "thaumicaugmentation:fortified_glass@0"
            ]
        },
        {
            "x": 3,
            "y": 7,
            "z": 10,
            "elements": [
                "thaumicaugmentation:fortified_glass@0"
            ]
        },
        {
            "x": 4,
            "y": -1,
            "z": 7,
            "elements": [
                "thaumicaugmentation:fortified_glass@0"
            ]
        },
        {
            "x": -5,
            "y": 6,
            "z": 8,
            "elements": [
                "thaumicaugmentation:fortified_glass@0"
            ]
        },
        {
            "x": 4,
            "y": -1,
            "z": 3,
            "elements": [
                "thaumicaugmentation:fortified_glass@0"
            ]
        },
        {
            "x": 5,
            "y": 0,
            "z": 7,
            "elements": [
                "thaumcraft:metal_thaumium@0"
            ]
        },
        {
            "x": 1,
            "y": 9,
            "z": 7,
            "elements": [
                "thaumicaugmentation:fortified_glass@0"
            ]
        },
        {
            "x": -5,
            "y": 5,
            "z": 8,
            "elements": [
                "thaumicaugmentation:fortified_glass@0"
            ]
        },
        {
            "x": 5,
            "y": 5,
            "z": 9,
            "elements": [
                "thaumicaugmentation:fortified_glass@0"
            ]
        },
        {
            "x": -1,
            "y": 9,
            "z": 3,
            "elements": [
                "thaumicaugmentation:fortified_glass@0"
            ]
        },
        {
            "x": 4,
            "y": 5,
            "z": 10,
            "elements": [
                "thaumicaugmentation:fortified_glass@0"
            ]
        },
        {
            "x": -1,
            "y": -1,
            "z": 2,
            "elements": [
                "thaumicaugmentation:fortified_glass@0"
            ]
        },
        {
            "x": -5,
            "y": 6,
            "z": 1,
            "elements": [
                "thaumicaugmentation:fortified_glass@0"
            ]
        },
        {
            "x": 4,
            "y": 6,
            "z": 10,
            "elements": [
                "thaumicaugmentation:fortified_glass@0"
            ]
        },
        {
            "x": 5,
            "y": 0,
            "z": 3,
            "elements": [
                "thaumcraft:metal_thaumium@0"
            ]
        },
        {
            "x": 5,
            "y": 5,
            "z": 3,
            "elements": [
                "thaumicaugmentation:fortified_glass@0"
            ]
        },
        {
            "x": 2,
            "y": 9,
            "z": 9,
            "elements": [
                "thaumicaugmentation:fortified_glass@0"
            ]
        },
        {
            "x": 3,
            "y": 8,
            "z": 10,
            "elements": [
                "thaumcraft:metal_thaumium@0"
            ]
        },
        {
            "x": 5,
            "y": 1,
            "z": 7,
            "elements": [
                "thaumicaugmentation:fortified_glass@0"
            ]
        },
        {
            "x": -5,
            "y": 7,
            "z": 2,
            "elements": [
                "thaumicaugmentation:fortified_glass@0"
            ]
        },
        {
            "x": -1,
            "y": -1,
            "z": 9,
            "elements": [
                "thaumicaugmentation:fortified_glass@0"
            ]
        },
        {
            "x": -5,
            "y": 3,
            "z": 8,
            "elements": [
                "thaumicaugmentation:fortified_glass@0"
            ]
        },
        {
            "x": 5,
            "y": 0,
            "z": 6,
            "elements": [
                "thaumcraft:metal_thaumium@0"
            ]
        },
        {
            "x": -5,
            "y": 0,
            "z": 1,
            "elements": [
                "thaumcraft:metal_thaumium@0"
            ]
        },
        {
            "x": 2,
            "y": 9,
            "z": 7,
            "elements": [
                "thaumicaugmentation:fortified_glass@0"
            ]
        },
        {
            "x": -5,
            "y": 8,
            "z": 2,
            "elements": [
                "thaumcraft:metal_thaumium@0"
            ]
        },
        {
            "x": 2,
            "y": 9,
            "z": 3,
            "elements": [
                "thaumicaugmentation:fortified_glass@0"
            ]
        },
        {
            "x": -5,
            "y": 1,
            "z": 1,
            "elements": [
                "thaumicaugmentation:fortified_glass@0"
            ]
        },
        {
            "x": 5,
            "y": 2,
            "z": 7,
            "elements": [
                "thaumicaugmentation:fortified_glass@0"
            ]
        },
        {
            "x": 5,
            "y": 3,
            "z": 7,
            "elements": [
                "thaumicaugmentation:fortified_glass@0"
            ]
        },
        {
            "x": -2,
            "y": -1,
            "z": 2,
            "elements": [
                "thaumicaugmentation:fortified_glass@0"
            ]
        },
        {
            "x": -2,
            "y": 9,
            "z": 1,
            "elements": [
                "thaumicaugmentation:fortified_glass@0"
            ]
        },
        {
            "x": 5,
            "y": 1,
            "z": 6,
            "elements": [
                "thaumicaugmentation:fortified_glass@0"
            ]
        },
        {
            "x": -5,
            "y": 6,
            "z": 2,
            "elements": [
                "thaumicaugmentation:fortified_glass@0"
            ]
        },
        {
            "x": -2,
            "y": 9,
            "z": 4,
            "elements": [
                "thaumicaugmentation:fortified_glass@0"
            ]
        },
        {
            "x": -5,
            "y": 4,
            "z": 8,
            "elements": [
                "thaumicaugmentation:fortified_glass@0"
            ]
        },
        {
            "x": -3,
            "y": -1,
            "z": 8,
            "elements": [
                "thaumicaugmentation:fortified_glass@0"
            ]
        },
        {
            "x": -5,
            "y": 9,
            "z": 2,
            "elements": [
                "thaumadditions:brass_plated_silverwood@0"
            ]
        },
        {
            "x": 3,
            "y": -1,
            "z": 1,
            "elements": [
                "thaumicaugmentation:fortified_glass@0"
            ]
        },
        {
            "x": -5,
            "y": 5,
            "z": 2,
            "elements": [
                "thaumicaugmentation:fortified_glass@0"
            ]
        },
        {
            "x": 5,
            "y": 4,
            "z": 7,
            "elements": [
                "thaumicaugmentation:fortified_glass@0"
            ]
        },
        {
            "x": -5,
            "y": 1,
            "z": 8,
            "elements": [
                "thaumicaugmentation:fortified_glass@0"
            ]
        },
        {
            "x": 1,
            "y": -1,
            "z": 2,
            "elements": [
                "thaumicaugmentation:fortified_glass@0"
            ]
        },
        {
            "x": 1,
            "y": 9,
            "z": 3,
            "elements": [
                "thaumicaugmentation:fortified_glass@0"
            ]
        },
        {
            "x": 3,
            "y": 9,
            "z": 5,
            "elements": [
                "thaumicaugmentation:fortified_glass@0"
            ]
        },
        {
            "x": 5,
            "y": 2,
            "z": 3,
            "elements": [
                "thaumicaugmentation:fortified_glass@0"
            ]
        },
        {
            "x": -1,
            "y": 9,
            "z": 7,
            "elements": [
                "thaumicaugmentation:fortified_glass@0"
            ]
        },
        {
            "x": -5,
            "y": 2,
            "z": 1,
            "elements": [
                "thaumicaugmentation:fortified_glass@0"
            ]
        },
        {
            "x": 5,
            "y": -1,
            "z": 10,
            "elements": [
                "thaumadditions:brass_plated_silverwood@0"
            ]
        },
        {
            "x": 5,
            "y": 5,
            "z": 7,
            "elements": [
                "thaumicaugmentation:fortified_glass@0"
            ]
        },
        {
            "x": -5,
            "y": 2,
            "z": 8,
            "elements": [
                "thaumicaugmentation:fortified_glass@0"
            ]
        },
        {
            "x": 3,
            "y": 3,
            "z": 10,
            "elements": [
                "thaumicaugmentation:fortified_glass@0"
            ]
        },
        {
            "x": -5,
            "y": 3,
            "z": 1,
            "elements": [
                "thaumicaugmentation:fortified_glass@0"
            ]
        },
        {
            "x": 4,
            "y": 9,
            "z": 10,
            "elements": [
                "thaumadditions:brass_plated_silverwood@0"
            ]
        },
        {
            "x": 3,
            "y": 4,
            "z": 10,
            "elements": [
                "thaumicaugmentation:fortified_glass@0"
            ]
        },
        {
            "x": -5,
            "y": 4,
            "z": 2,
            "elements": [
                "thaumicaugmentation:fortified_glass@0"
            ]
        },
        {
            "x": 5,
            "y": 1,
            "z": 3,
            "elements": [
                "thaumicaugmentation:fortified_glass@0"
            ]
        },
        {
            "x": 4,
            "y": -1,
            "z": 6,
            "elements": [
                "thaumicaugmentation:fortified_glass@0"
            ]
        },
        {
            "x": -4,
            "y": -1,
            "z": 8,
            "elements": [
                "thaumicaugmentation:fortified_glass@0"
            ]
        },
        {
            "x": 5,
            "y": 5,
            "z": 0,
            "elements": [
                "thaumadditions:brass_plated_silverwood@0"
            ]
        },
        {
            "x": 4,
            "y": -1,
            "z": 10,
            "elements": [
                "thaumadditions:brass_plated_silverwood@0"
            ]
        },
        {
            "x": -1,
            "y": 5,
            "z": 10,
            "elements": [
                "thaumicaugmentation:fortified_glass@0"
            ]
        },
        {
            "x": -5,
            "y": 3,
            "z": 2,
            "elements": [
                "thaumicaugmentation:fortified_glass@0"
            ]
        },
        {
            "x": 3,
            "y": 9,
            "z": 0,
            "elements": [
                "thaumadditions:brass_plated_silverwood@0"
            ]
        },
        {
            "x": 2,
            "y": 1,
            "z": 10,
            "elements": [
                "thaumicaugmentation:fortified_glass@0"
            ]
        },
        {
            "x": 5,
            "y": 9,
            "z": 9,
            "elements": [
                "thaumadditions:brass_plated_silverwood@0"
            ]
        },
        {
            "x": 2,
            "y": 0,
            "z": 10,
            "elements": [
                "thaumcraft:metal_thaumium@0"
            ]
        },
        {
            "x": 5,
            "y": 6,
            "z": 0,
            "elements": [
                "thaumadditions:brass_plated_silverwood@0"
            ]
        },
        {
            "x": -3,
            "y": -1,
            "z": 1,
            "elements": [
                "thaumicaugmentation:fortified_glass@0"
            ]
        },
        {
            "x": -1,
            "y": -1,
            "z": 6,
            "elements": [
                "thaumicaugmentation:fortified_glass@0"
            ]
        },
        {
            "x": 2,
            "y": 4,
            "z": 10,
            "elements": [
                "thaumicaugmentation:fortified_glass@0"
            ]
        },
        {
            "x": -5,
            "y": 2,
            "z": 2,
            "elements": [
                "thaumicaugmentation:fortified_glass@0"
            ]
        },
        {
            "x": -1,
            "y": 6,
            "z": 10,
            "elements": [
                "thaumicaugmentation:fortified_glass@0"
            ]
        },
        {
            "x": -5,
            "y": 0,
            "z": 2,
            "elements": [
                "thaumcraft:metal_thaumium@0"
            ]
        },
        {
            "x": 0,
            "y": -1,
            "z": 7,
            "elements": [
                "thaumicaugmentation:fortified_glass@0"
            ]
        },
        {
            "x": -1,
            "y": 7,
            "z": 10,
            "elements": [
                "thaumicaugmentation:fortified_glass@0"
            ]
        },
        {
            "x": 4,
            "y": 9,
            "z": 8,
            "elements": [
                "thaumicaugmentation:fortified_glass@0"
            ]
        },
        {
            "x": 2,
            "y": 9,
            "z": 0,
            "elements": [
                "thaumadditions:brass_plated_silverwood@0"
            ]
        },
        {
            "x": 1,
            "y": 9,
            "z": 5,
            "elements": [
                "thaumicaugmentation:fortified_glass@0"
            ]
        },
        {
            "x": 5,
            "y": 7,
            "z": 0,
            "elements": [
                "thaumadditions:brass_plated_silverwood@0"
            ]
        },
        {
            "x": 2,
            "y": 3,
            "z": 10,
            "elements": [
                "thaumicaugmentation:fortified_glass@0"
            ]
        },
        {
            "x": -4,
            "y": 9,
            "z": 1,
            "elements": [
                "thaumicaugmentation:fortified_glass@0"
            ]
        },
        {
            "x": 3,
            "y": -1,
            "z": 2,
            "elements": [
                "thaumicaugmentation:fortified_glass@0"
            ]
        },
        {
            "x": -1,
            "y": 8,
            "z": 10,
            "elements": [
                "thaumcraft:metal_thaumium@0"
            ]
        },
        {
            "x": -5,
            "y": 1,
            "z": 2,
            "elements": [
                "thaumicaugmentation:fortified_glass@0"
            ]
        },
        {
            "x": 5,
            "y": 8,
            "z": 0,
            "elements": [
                "thaumadditions:brass_plated_silverwood@0"
            ]
        },
        {
            "x": 2,
            "y": 2,
            "z": 10,
            "elements": [
                "thaumicaugmentation:fortified_glass@0"
            ]
        },
        {
            "x": 2,
            "y": -1,
            "z": 6,
            "elements": [
                "thaumicaugmentation:fortified_glass@0"
            ]
        },
        {
            "x": 1,
            "y": 9,
            "z": 8,
            "elements": [
                "thaumicaugmentation:fortified_glass@0"
            ]
        },
        {
            "x": 2,
            "y": -1,
            "z": 1,
            "elements": [
                "thaumicaugmentation:fortified_glass@0"
            ]
        },
        {
            "x": 3,
            "y": 5,
            "z": 0,
            "elements": [
                "thaumicaugmentation:fortified_glass@0"
            ]
        },
        {
            "x": 3,
            "y": -1,
            "z": 7,
            "elements": [
                "thaumicaugmentation:fortified_glass@0"
            ]
        },
        {
            "x": 5,
            "y": 6,
            "z": 9,
            "elements": [
                "thaumicaugmentation:fortified_glass@0"
            ]
        },
        {
            "x": -5,
            "y": 6,
            "z": 7,
            "elements": [
                "thaumicaugmentation:fortified_glass@0"
            ]
        },
        {
            "x": -2,
            "y": 9,
            "z": 7,
            "elements": [
                "thaumicaugmentation:fortified_glass@0"
            ]
        },
        {
            "x": 5,
            "y": 7,
            "z": 3,
            "elements": [
                "thaumicaugmentation:fortified_glass@0"
            ]
        },
        {
            "x": 5,
            "y": 9,
            "z": 0,
            "elements": [
                "thaumadditions:brass_plated_silverwood@0"
            ]
        },
        {
            "x": -5,
            "y": 9,
            "z": 1,
            "elements": [
                "thaumadditions:brass_plated_silverwood@0"
            ]
        },
        {
            "x": 3,
            "y": 6,
            "z": 0,
            "elements": [
                "thaumicaugmentation:fortified_glass@0"
            ]
        },
        {
            "x": -1,
            "y": -1,
            "z": 1,
            "elements": [
                "thaumicaugmentation:fortified_glass@0"
            ]
        },
        {
            "x": -5,
            "y": 7,
            "z": 7,
            "elements": [
                "thaumicaugmentation:fortified_glass@0"
            ]
        },
        {
            "x": -5,
            "y": 8,
            "z": 1,
            "elements": [
                "thaumcraft:metal_thaumium@0"
            ]
        },
        {
            "x": 5,
            "y": 8,
            "z": 3,
            "elements": [
                "thaumcraft:metal_thaumium@0"
            ]
        },
        {
            "x": 1,
            "y": -1,
            "z": 10,
            "elements": [
                "thaumadditions:brass_plated_silverwood@0"
            ]
        },
        {
            "x": -5,
            "y": 8,
            "z": 7,
            "elements": [
                "thaumcraft:metal_thaumium@0"
            ]
        },
        {
            "x": -3,
            "y": 9,
            "z": 6,
            "elements": [
                "thaumicaugmentation:fortified_glass@0"
            ]
        },
        {
            "x": 5,
            "y": 8,
            "z": 9,
            "elements": [
                "thaumcraft:metal_thaumium@0"
            ]
        },
        {
            "x": 3,
            "y": 7,
            "z": 0,
            "elements": [
                "thaumicaugmentation:fortified_glass@0"
            ]
        },
        {
            "x": 5,
            "y": 9,
            "z": 3,
            "elements": [
                "thaumadditions:brass_plated_silverwood@0"
            ]
        },
        {
            "x": 0,
            "y": 9,
            "z": 0,
            "elements": [
                "thaumadditions:brass_plated_silverwood@0"
            ]
        },
        {
            "x": 0,
            "y": -1,
            "z": 1,
            "elements": [
                "thaumicaugmentation:fortified_glass@0"
            ]
        },
        {
            "x": -5,
            "y": 9,
            "z": 7,
            "elements": [
                "thaumadditions:brass_plated_silverwood@0"
            ]
        },
        {
            "x": 4,
            "y": 9,
            "z": 9,
            "elements": [
                "thaumicaugmentation:fortified_glass@0"
            ]
        },
        {
            "x": -3,
            "y": -1,
            "z": 2,
            "elements": [
                "thaumicaugmentation:fortified_glass@0"
            ]
        },
        {
            "x": 5,
            "y": 7,
            "z": 9,
            "elements": [
                "thaumicaugmentation:fortified_glass@0"
            ]
        },
        {
            "x": 3,
            "y": 8,
            "z": 0,
            "elements": [
                "thaumcraft:metal_thaumium@0"
            ]
        },
        {
            "x": -5,
            "y": 9,
            "z": 8,
            "elements": [
                "thaumadditions:brass_plated_silverwood@0"
            ]
        },
        {
            "x": 0,
            "y": 7,
            "z": 0,
            "elements": [
                "thaumicaugmentation:fortified_glass@0"
            ]
        },
        {
            "x": -1,
            "y": 3,
            "z": 10,
            "elements": [
                "thaumicaugmentation:fortified_glass@0"
            ]
        },
        {
            "x": 5,
            "y": 3,
            "z": 4,
            "elements": [
                "thaumicaugmentation:fortified_glass@0"
            ]
        },
        {
            "x": -5,
            "y": -1,
            "z": 6,
            "elements": [
                "thaumadditions:brass_plated_silverwood@0"
            ]
        },
        {
            "x": -1,
            "y": 4,
            "z": 10,
            "elements": [
                "thaumicaugmentation:fortified_glass@0"
            ]
        },
        {
            "x": 5,
            "y": 4,
            "z": 4,
            "elements": [
                "thaumicaugmentation:fortified_glass@0"
            ]
        },
        {
            "x": 4,
            "y": 9,
            "z": 5,
            "elements": [
                "thaumicaugmentation:fortified_glass@0"
            ]
        },
        {
            "x": 3,
            "y": 2,
            "z": 0,
            "elements": [
                "thaumicaugmentation:fortified_glass@0"
            ]
        },
        {
            "x": -5,
            "y": 7,
            "z": 6,
            "elements": [
                "thaumicaugmentation:fortified_glass@0"
            ]
        },
        {
            "x": 0,
            "y": 8,
            "z": 0,
            "elements": [
                "extrautils2:redstonelantern"
            ]
        },
        {
            "x": -3,
            "y": 9,
            "z": 1,
            "elements": [
                "thaumicaugmentation:fortified_glass@0"
            ]
        },
        {
            "x": -4,
            "y": 7,
            "z": 10,
            "elements": [
                "thaumicaugmentation:fortified_glass@0"
            ]
        },
        {
            "x": -3,
            "y": -1,
            "z": 7,
            "elements": [
                "thaumicaugmentation:fortified_glass@0"
            ]
        },
        {
            "x": 1,
            "y": -1,
            "z": 1,
            "elements": [
                "thaumicaugmentation:fortified_glass@0"
            ]
        },
        {
            "x": 1,
            "y": 9,
            "z": 2,
            "elements": [
                "thaumicaugmentation:fortified_glass@0"
            ]
        },
        {
            "x": 0,
            "y": 9,
            "z": 1,
            "elements": [
                "thaumicaugmentation:fortified_glass@0"
            ]
        },
        {
            "x": -4,
            "y": 5,
            "z": 10,
            "elements": [
                "thaumicaugmentation:fortified_glass@0"
            ]
        },
        {
            "x": -4,
            "y": 8,
            "z": 10,
            "elements": [
                "thaumcraft:metal_thaumium@0"
            ]
        },
        {
            "x": -4,
            "y": -1,
            "z": 0,
            "elements": [
                "thaumadditions:brass_plated_silverwood@0"
            ]
        },
        {
            "x": 3,
            "y": 1,
            "z": 0,
            "elements": [
                "thaumicaugmentation:fortified_glass@0"
            ]
        },
        {
            "x": -1,
            "y": 2,
            "z": 10,
            "elements": [
                "thaumicaugmentation:fortified_glass@0"
            ]
        },
        {
            "x": -3,
            "y": 0,
            "z": 0,
            "elements": [
                "thaumcraft:metal_thaumium@0"
            ]
        },
        {
            "x": -1,
            "y": 1,
            "z": 10,
            "elements": [
                "thaumicaugmentation:fortified_glass@0"
            ]
        },
        {
            "x": 5,
            "y": 6,
            "z": 4,
            "elements": [
                "thaumicaugmentation:fortified_glass@0"
            ]
        },
        {
            "x": 1,
            "y": -1,
            "z": 8,
            "elements": [
                "thaumicaugmentation:fortified_glass@0"
            ]
        },
        {
            "x": -5,
            "y": 6,
            "z": 6,
            "elements": [
                "thaumicaugmentation:fortified_glass@0"
            ]
        },
        {
            "x": -5,
            "y": 3,
            "z": 7,
            "elements": [
                "thaumicaugmentation:fortified_glass@0"
            ]
        },
        {
            "x": -2,
            "y": -1,
            "z": 6,
            "elements": [
                "thaumicaugmentation:fortified_glass@0"
            ]
        },
        {
            "x": -5,
            "y": 4,
            "z": 7,
            "elements": [
                "thaumicaugmentation:fortified_glass@0"
            ]
        },
        {
            "x": -5,
            "y": 9,
            "z": 6,
            "elements": [
                "thaumadditions:brass_plated_silverwood@0"
            ]
        },
        {
            "x": -4,
            "y": -1,
            "z": 7,
            "elements": [
                "thaumicaugmentation:fortified_glass@0"
            ]
        },
        {
            "x": 0,
            "y": 6,
            "z": 0,
            "elements": [
                "thaumicaugmentation:fortified_glass@0"
            ]
        },
        {
            "x": 3,
            "y": 4,
            "z": 0,
            "elements": [
                "thaumicaugmentation:fortified_glass@0"
            ]
        },
        {
            "x": -1,
            "y": 0,
            "z": 10,
            "elements": [
                "thaumcraft:metal_thaumium@0"
            ]
        },
        {
            "x": -5,
            "y": 1,
            "z": 7,
            "elements": [
                "thaumicaugmentation:fortified_glass@0"
            ]
        },
        {
            "x": -2,
            "y": -1,
            "z": 1,
            "elements": [
                "thaumicaugmentation:fortified_glass@0"
            ]
        },
        {
            "x": 0,
            "y": 5,
            "z": 0,
            "elements": [
                "thaumicaugmentation:fortified_glass@0"
            ]
        },
        {
            "x": -5,
            "y": 5,
            "z": 7,
            "elements": [
                "thaumicaugmentation:fortified_glass@0"
            ]
        },
        {
            "x": -5,
            "y": 2,
            "z": 7,
            "elements": [
                "thaumicaugmentation:fortified_glass@0"
            ]
        },
        {
            "x": -1,
            "y": 9,
            "z": 10,
            "elements": [
                "thaumadditions:brass_plated_silverwood@0"
            ]
        },
        {
            "x": 5,
            "y": 3,
            "z": 10,
            "elements": [
                "thaumadditions:brass_plated_silverwood@0"
            ]
        },
        {
            "x": -4,
            "y": 6,
            "z": 10,
            "elements": [
                "thaumicaugmentation:fortified_glass@0"
            ]
        },
        {
            "x": 3,
            "y": 3,
            "z": 0,
            "elements": [
                "thaumicaugmentation:fortified_glass@0"
            ]
        },
        {
            "x": 0,
            "y": -1,
            "z": 5,
            "elements": [
                "thaumicaugmentation:fortified_glass@0"
            ]
        },
        {
            "x": 2,
            "y": 9,
            "z": 10,
            "elements": [
                "thaumadditions:brass_plated_silverwood@0"
            ]
        },
        {
            "x": -1,
            "y": -1,
            "z": 7,
            "elements": [
                "thaumicaugmentation:fortified_glass@0"
            ]
        },
        {
            "x": 5,
            "y": 4,
            "z": 10,
            "elements": [
                "thaumadditions:brass_plated_silverwood@0"
            ]
        },
        {
            "x": 5,
            "y": 5,
            "z": 4,
            "elements": [
                "thaumicaugmentation:fortified_glass@0"
            ]
        },
        {
            "x": -5,
            "y": 8,
            "z": 6,
            "elements": [
                "thaumcraft:metal_thaumium@0"
            ]
        },
        {
            "x": 2,
            "y": 7,
            "z": 10,
            "elements": [
                "thaumicaugmentation:fortified_glass@0"
            ]
        },
        {
            "x": 5,
            "y": 5,
            "z": 10,
            "elements": [
                "thaumadditions:brass_plated_silverwood@0"
            ]
        },
        {
            "x": -3,
            "y": 2,
            "z": 0,
            "elements": [
                "thaumicaugmentation:fortified_glass@0"
            ]
        },
        {
            "x": -5,
            "y": 4,
            "z": 6,
            "elements": [
                "thaumicaugmentation:fortified_glass@0"
            ]
        },
        {
            "x": -3,
            "y": -1,
            "z": 6,
            "elements": [
                "thaumicaugmentation:fortified_glass@0"
            ]
        },
        {
            "x": 5,
            "y": 9,
            "z": 4,
            "elements": [
                "thaumadditions:brass_plated_silverwood@0"
            ]
        },
        {
            "x": 4,
            "y": -1,
            "z": 8,
            "elements": [
                "thaumicaugmentation:fortified_glass@0"
            ]
        },
        {
            "x": 5,
            "y": 8,
            "z": 4,
            "elements": [
                "thaumcraft:metal_thaumium@0"
            ]
        },
        {
            "x": 0,
            "y": 4,
            "z": 0,
            "elements": [
                "thaumicaugmentation:fortified_glass@0"
            ]
        },
        {
            "x": 5,
            "y": -1,
            "z": 0,
            "elements": [
                "thaumadditions:brass_plated_silverwood@0"
            ]
        },
        {
            "x": -2,
