{
    "registryname": "energy_field_emitter",
    "localizedname": "Energy Field Emitter",
    "color": "cad6dc",
    "parts": [
        {
            "x": -2,
            "y": -1,
            "z": 12,
            "elements": [
                "contenttweaker:superconductor@0"
            ]
        },
        {
            "x": 1,
            "y": -1,
            "z": 7,
            "elements": [
                "enderio:block_alloy@4"
            ]
        },
        {
            "x": -3,
            "y": 0,
            "z": 1,
            "elements": [
                "nuclearcraft:ingot_block@10"
            ]
        },
        {
            "x": -2,
            "y": 1,
            "z": 12,
            "elements": [
                "contenttweaker:superconductor@0"
            ]
        },
        {
            "x": 1,
            "y": 1,
            "z": 7,
            "elements": [
                "enderio:block_alloy@4"
            ]
        },
        {
            "x": 6,
            "y": -1,
            "z": 4,
            "elements": [
                "contenttweaker:superconductor@0"
            ]
        },
        {
            "x": 4,
            "y": 0,
            "z": 11,
            "elements": [
                "nuclearcraft:ingot_block@10"
            ]
        },
        {
            "x": -5,
            "y": -1,
            "z": 3,
            "elements": [
                "contenttweaker:superconductor@0"
            ]
        },
        {
            "x": -1,
            "y": 1,
            "z": 0,
            "elements": [
                "contenttweaker:superconductor@0"
            ]
        },
        {
            "x": 0,
            "y": -1,
            "z": 0,
            "elements": [
                "contenttweaker:superconductor@0"
            ]
        },
        {
            "x": -2,
            "y": 0,
            "z": 12,
            "elements": [
                "nuclearcraft:ingot_block@10"
            ]
        },
        {
            "x": -3,
            "y": -1,
            "z": 1,
            "elements": [
                "contenttweaker:superconductor@0"
            ]
        },
        {
            "x": -1,
            "y": -1,
            "z": 6,
            "elements": [
                "enderio:block_alloy@4"
            ]
        },
        {
            "x": 5,
            "y": 0,
            "z": 9,
            "elements": [
                "nuclearcraft:ingot_block@10"
            ]
        },
        {
            "x": 4,
            "y": 1,
            "z": 11,
            "elements": [
                "contenttweaker:superconductor@0"
            ]
        },
        {
            "x": -4,
            "y": 1,
            "z": 11,
            "elements": [
                "contenttweaker:superconductor@0"
            ]
        },
        {
            "x": -3,
            "y": 1,
            "z": 1,
            "elements": [
                "contenttweaker:superconductor@0"
            ]
        },
        {
            "x": 0,
            "y": -1,
            "z": 7,
            "elements": [
                "enderio:block_alloy@4"
            ]
        },
        {
            "x": 1,
            "y": 0,
            "z": 0,
            "elements": [
                "nuclearcraft:ingot_block@10"
            ]
        },
        {
            "x": -5,
            "y": 0,
            "z": 2,
            "elements": [
                "nuclearcraft:ingot_block@10"
            ]
        },
        {
            "x": -6,
            "y": 1,
            "z": 7,
            "elements": [
                "contenttweaker:superconductor@0"
            ]
        },
        {
            "x": 6,
            "y": 1,
            "z": 5,
            "elements": [
                "contenttweaker:superconductor@0"
            ]
        },
        {
            "x": -1,
            "y": -1,
            "z": 12,
            "elements": [
                "contenttweaker:superconductor@0"
            ]
        },
        {
            "x": -6,
            "y": -1,
            "z": 6,
            "elements": [
                "contenttweaker:superconductor@0"
            ]
        },
        {
            "x": -5,
            "y": 1,
            "z": 10,
            "elements": [
                "contenttweaker:superconductor@0"
            ]
        },
        {
            "x": 0,
            "y": 0,
            "z": 6,
            "elements": [
                "modularmachinery:blockoutputbus"
            ]
        },
        {
            "x": 0,
            "y": 2,
            "z": 6,
            "elements": [
                "modularmachinery:blockinputbus"
            ]
        },
        {
            "x": 1,
            "y": -1,
            "z": 0,
            "elements": [
                "contenttweaker:superconductor@0"
            ]
        },
        {
            "x": -2,
            "y": 1,
            "z": 0,
            "elements": [
                "contenttweaker:superconductor@0"
            ]
        },
        {
            "x": -5,
            "y": -1,
            "z": 9,
            "elements": [
                "contenttweaker:superconductor@0"
            ]
        },
        {
            "x": 6,
            "y": 0,
            "z": 5,
            "elements": [
                "nuclearcraft:ingot_block@10"
            ]
        },
        {
            "x": -5,
            "y": 1,
            "z": 2,
            "elements": [
                "contenttweaker:superconductor@0"
            ]
        },
        {
            "x": -5,
            "y": 0,
            "z": 10,
            "elements": [
                "nuclearcraft:ingot_block@10"
            ]
        },
        {
            "x": -4,
            "y": 0,
            "z": 11,
            "elements": [
                "nuclearcraft:ingot_block@10"
            ]
        },
        {
            "x": -5,
            "y": -1,
            "z": 2,
            "elements": [
                "contenttweaker:superconductor@0"
            ]
        },
        {
            "x": 0,
            "y": 1,
            "z": 6,
            "elements": [
                "enderio:block_alloy@4"
            ]
        },
        {
            "x": 6,
            "y": 0,
            "z": 8,
            "elements": [
                "nuclearcraft:ingot_block@10"
            ]
        },
        {
            "x": -5,
            "y": -1,
            "z": 10,
            "elements": [
                "contenttweaker:superconductor@0"
            ]
        },
        {
            "x": -6,
            "y": -1,
            "z": 8,
            "elements": [
                "contenttweaker:superconductor@0"
            ]
        },
        {
            "x": -5,
            "y": 1,
            "z": 9,
            "elements": [
                "contenttweaker:superconductor@0"
            ]
        },
        {
            "x": -6,
            "y": 0,
            "z": 7,
            "elements": [
                "nuclearcraft:ingot_block@10"
            ]
        },
        {
            "x": 2,
            "y": 0,
            "z": 0,
            "elements": [
                "nuclearcraft:ingot_block@10"
            ]
        },
        {
            "x": -5,
            "y": 0,
            "z": 9,
            "elements": [
                "nuclearcraft:ingot_block@10"
            ]
        },
        {
            "x": 6,
            "y": 1,
            "z": 4,
            "elements": [
                "contenttweaker:superconductor@0"
            ]
        },
        {
            "x": 0,
            "y": -1,
            "z": 12,
            "elements": [
                "contenttweaker:superconductor@0"
            ]
        },
        {
            "x": -1,
            "y": 1,
            "z": 7,
            "elements": [
                "enderio:block_alloy@4"
            ]
        },
        {
            "x": -5,
            "y": 1,
            "z": 3,
            "elements": [
                "contenttweaker:superconductor@0"
            ]
        },
        {
            "x": 0,
            "y": 1,
            "z": 12,
            "elements": [
                "contenttweaker:superconductor@0"
            ]
        },
        {
            "x": 6,
            "y": 1,
            "z": 8,
            "elements": [
                "contenttweaker:superconductor@0"
            ]
        },
        {
            "x": -6,
            "y": 0,
            "z": 8,
            "elements": [
                "nuclearcraft:ingot_block@10"
            ]
        },
        {
            "x": 1,
            "y": 1,
            "z": 0,
            "elements": [
                "contenttweaker:superconductor@0"
            ]
        },
        {
            "x": -2,
            "y": -1,
            "z": 0,
            "elements": [
                "contenttweaker:superconductor@0"
            ]
        },
        {
            "x": -1,
            "y": -1,
            "z": 5,
            "elements": [
                "enderio:block_alloy@4"
            ]
        },
        {
            "x": 0,
            "y": 0,
            "z": 12,
            "elements": [
                "gugu-utils:emberinputhatch"
            ]
        },
        {
            "x": 1,
            "y": -1,
            "z": 6,
            "elements": [
                "enderio:block_alloy@4"
            ]
        },
        {
            "x": 1,
            "y": 1,
            "z": 6,
            "elements": [
                "enderio:block_alloy@4"
            ]
        },
        {
            "x": -1,
            "y": 0,
            "z": 0,
            "elements": [
                "nuclearcraft:ingot_block@10"
            ]
        },
        {
            "x": 5,
            "y": 1,
            "z": 9,
            "elements": [
                "contenttweaker:superconductor@0"
            ]
        },
        {
            "x": 5,
            "y": 1,
            "z": 2,
            "elements": [
                "contenttweaker:superconductor@0"
            ]
        },
        {
            "x": 6,
            "y": -1,
            "z": 7,
            "elements": [
                "contenttweaker:superconductor@0"
            ]
        },
        {
            "x": 5,
            "y": -1,
            "z": 2,
            "elements": [
                "contenttweaker:superconductor@0"
            ]
        },
        {
            "x": -6,
            "y": -1,
            "z": 5,
            "elements": [
                "contenttweaker:superconductor@0"
            ]
        },
        {
            "x": -6,
            "y": 0,
            "z": 6,
            "elements": [
                "modularmachinery:blockenergyinputhatch"
            ]
        },
        {
            "x": 0,
            "y": -1,
            "z": 6,
            "elements": [
                "enderio:block_alloy@4"
            ]
        },
        {
            "x": -6,
            "y": 1,
            "z": 6,
            "elements": [
                "contenttweaker:superconductor@0"
            ]
        },
        {
            "x": 5,
            "y": -1,
            "z": 9,
            "elements": [
                "contenttweaker:superconductor@0"
            ]
        },
        {
            "x": -5,
            "y": 0,
            "z": 3,
            "elements": [
                "nuclearcraft:ingot_block@10"
            ]
        },
        {
            "x": 5,
            "y": 0,
            "z": 2,
            "elements": [
                "nuclearcraft:ingot_block@10"
            ]
        },
        {
            "x": 0,
            "y": 1,
            "z": 5,
            "elements": [
                "enderio:block_alloy@4"
            ]
        },
        {
            "x": 6,
            "y": 0,
            "z": 4,
            "elements": [
                "nuclearcraft:ingot_block@10"
            ]
        },
        {
            "x": -3,
            "y": 1,
            "z": 11,
            "elements": [
                "contenttweaker:superconductor@0"
            ]
        },
        {
            "x": -3,
            "y": -1,
            "z": 11,
            "elements": [
                "contenttweaker:superconductor@0"
            ]
        },
        {
            "x": 2,
            "y": -1,
            "z": 12,
            "elements": [
                "contenttweaker:superconductor@0"
            ]
        },
        {
            "x": 2,
            "y": 1,
            "z": 12,
            "elements": [
                "contenttweaker:superconductor@0"
            ]
        },
        {
            "x": 6,
            "y": -1,
            "z": 8,
            "elements": [
                "contenttweaker:superconductor@0"
            ]
        },
        {
            "x": -3,
            "y": 0,
            "z": 11,
            "elements": [
                "nuclearcraft:ingot_block@10"
            ]
        },
        {
            "x": 2,
            "y": 0,
            "z": 12,
            "elements": [
                "nuclearcraft:ingot_block@10"
            ]
        },
        {
            "x": 1,
            "y": -1,
            "z": 5,
            "elements": [
                "enderio:block_alloy@4"
            ]
        },
        {
            "x": 1,
            "y": 1,
            "z": 5,
            "elements": [
                "enderio:block_alloy@4"
            ]
        },
        {
            "x": -1,
            "y": 1,
            "z": 6,
            "elements": [
                "enderio:block_alloy@4"
            ]
        },
        {
            "x": -4,
            "y": 0,
            "z": 1,
            "elements": [
                "nuclearcraft:ingot_block@10"
            ]
        },
        {
            "x": -6,
            "y": 0,
            "z": 5,
            "elements": [
                "nuclearcraft:ingot_block@10"
            ]
        },
        {
            "x": 1,
            "y": 1,
            "z": 12,
            "elements": [
                "contenttweaker:superconductor@0"
            ]
        },
        {
            "x": 4,
            "y": 0,
            "z": 1,
            "elements": [
                "nuclearcraft:ingot_block@10"
            ]
        },
        {
            "x": 3,
            "y": 0,
            "z": 11,
            "elements": [
                "nuclearcraft:ingot_block@10"
            ]
        },
        {
            "x": -4,
            "y": 1,
            "z": 1,
            "elements": [
                "contenttweaker:superconductor@0"
            ]
        },
        {
            "x": 5,
            "y": 0,
            "z": 3,
            "elements": [
                "nuclearcraft:ingot_block@10"
            ]
        },
        {
            "x": 2,
            "y": 1,
            "z": 0,
            "elements": [
                "contenttweaker:superconductor@0"
            ]
        },
        {
            "x": -6,
            "y": 1,
            "z": 5,
            "elements": [
                "contenttweaker:superconductor@0"
            ]
        },
        {
            "x": 1,
            "y": 0,
            "z": 12,
            "elements": [
                "nuclearcraft:ingot_block@10"
            ]
        },
        {
            "x": 4,
            "y": 1,
            "z": 1,
            "elements": [
                "contenttweaker:superconductor@0"
            ]
        },
        {
            "x": 0,
            "y": -1,
            "z": 5,
            "elements": [
                "enderio:block_alloy@4"
            ]
        },
        {
            "x": 5,
            "y": -1,
            "z": 3,
            "elements": [
                "contenttweaker:superconductor@0"
            ]
        },
        {
            "x": 6,
            "y": -1,
            "z": 6,
            "elements": [
                "contenttweaker:superconductor@0"
            ]
        },
        {
            "x": -2,
            "y": 0,
            "z": 0,
            "elements": [
                "nuclearcraft:ingot_block@10"
            ]
        },
        {
            "x": 3,
            "y": 1,
            "z": 11,
            "elements": [
                "contenttweaker:superconductor@0"
            ]
        },
        {
            "x": -1,
            "y": -1,
            "z": 7,
            "elements": [
                "enderio:block_alloy@4"
            ]
        },
        {
            "x": 3,
            "y": -1,
            "z": 11,
            "elements": [
                "contenttweaker:superconductor@0"
            ]
        },
        {
            "x": -6,
            "y": 0,
            "z": 4,
            "elements": [
                "nuclearcraft:ingot_block@10"
            ]
        },
        {
            "x": -6,
            "y": 1,
            "z": 8,
            "elements": [
                "contenttweaker:superconductor@0"
            ]
        },
        {
            "x": 6,
            "y": 0,
            "z": 7,
            "elements": [
                "nuclearcraft:ingot_block@10"
            ]
        },
        {
            "x": 3,
            "y": 0,
            "z": 1,
            "elements": [
                "nuclearcraft:ingot_block@10"
            ]
        },
        {
            "x": 3,
            "y": 1,
            "z": 1,
            "elements": [
                "contenttweaker:superconductor@0"
            ]
        },
        {
            "x": 6,
            "y": 1,
            "z": 7,
            "elements": [
                "contenttweaker:superconductor@0"
            ]
        },
        {
            "x": -1,
            "y": 1,
            "z": 5,
            "elements": [
                "enderio:block_alloy@4"
            ]
        },
        {
            "x": 3,
            "y": -1,
            "z": 1,
            "elements": [
                "contenttweaker:superconductor@0"
            ]
        },
        {
            "x": 6,
            "y": 0,
            "z": 6,
            "elements": [
                "modularmachinery:blockenergyinputhatch"
            ]
        },
        {
            "x": 4,
            "y": -1,
            "z": 11,
            "elements": [
                "contenttweaker:superconductor@0"
            ]
        },
        {
            "x": 1,
            "y": -1,
            "z": 12,
            "elements": [
                "contenttweaker:superconductor@0"
            ]
        },
        {
            "x": 0,
            "y": 1,
            "z": 7,
            "elements": [
                "enderio:block_alloy@4"
            ]
        },
        {
            "x": -4,
            "y": -1,
            "z": 11,
            "elements": [
                "contenttweaker:superconductor@0"
            ]
        },
        {
            "x": 5,
            "y": 1,
            "z": 10,
            "elements": [
                "contenttweaker:superconductor@0"
            ]
        },
        {
            "x": -6,
            "y": -1,
            "z": 7,
            "elements": [
                "contenttweaker:superconductor@0"
            ]
        },
        {
            "x": -1,
            "y": 1,
            "z": 12,
            "elements": [
                "contenttweaker:superconductor@0"
            ]
        },
        {
            "x": 5,
            "y": -1,
            "z": 10,
            "elements": [
                "contenttweaker:superconductor@0"
            ]
        },
        {
            "x": 0,
            "y": 1,
            "z": 0,
            "elements": [
                "contenttweaker:superconductor@0"
            ]
        },
        {
            "x": 2,
            "y": -1,
            "z": 0,
            "elements": [
                "contenttweaker:superconductor@0"
            ]
        },
        {
            "x": -1,
            "y": -1,
            "z": 0,
            "elements": [
                "contenttweaker:superconductor@0"
            ]
        },
        {
            "x": -6,
            "y": -1,
            "z": 4,
            "elements": [
                "contenttweaker:superconductor@0"
            ]
        },
        {
            "x": 6,
            "y": 1,
            "z": 6,
            "elements": [
                "contenttweaker:superconductor@0"
            ]
        },
        {
            "x": -6,
            "y": 1,
            "z": 4,
            "elements": [
                "contenttweaker:superconductor@0"
            ]
        },
        {
            "x": -4,
            "y": -1,
            "z": 1,
            "elements": [
                "contenttweaker:superconductor@0"
            ]
        },
        {
            "x": -1,
            "y": 0,
            "z": 12,
            "elements": [
                "nuclearcraft:ingot_block@10"
            ]
        },
        {
            "x": 6,
            "y": -1,
            "z": 5,
            "elements": [
                "contenttweaker:superconductor@0"
            ]
        },
        {
            "x": 4,
            "y": -1,
            "z": 1,
            "elements": [
                "contenttweaker:superconductor@0"
            ]
        },
        {
            "x": 5,
            "y": 1,
            "z": 3,
            "elements": [
                "contenttweaker:superconductor@0"
            ]
        },
        {
            "x": 5,
            "y": 0,
            "z": 10,
            "elements": [
                "nuclearcraft:ingot_block@10"
            ]
        }
    ]}