{
    "registryname": "time_transmutator",
    "localizedname": "Time Transmutator",
    "color": "cccccc",
    "parts": [
        {
            "x": 0,
            "y": -2,
            "z": 0,
            "elements": [
                "modularmachinery:blockoutputbus@0"
            ]
        },
        {
            "x": -4,
            "y": -2,
            "z": 2,
            "elements": [
                "compactmachines3:wallbreakable@0"
            ]
        },
        {
            "x": 5,
            "y": 0,
            "z": 1,
            "elements": [
                "compactmachines3:wall@0"
            ]
        },
        {
            "x": 5,
            "y": -2,
            "z": 1,
            "elements": [
                "compactmachines3:wall@0"
            ]
        },
        {
            "x": 0,
            "y": -1,
            "z": 0,
            "elements": [
                "actuallyadditions:block_misc@8"
            ]
        },
        {
            "x": 3,
            "y": 0,
            "z": -2,
            "elements": [
                "compactmachines3:wallbreakable@0"
            ]
        },
        {
            "x": -1,
            "y": -5,
            "z": -2,
            "elements": [
                "compactmachines3:wallbreakable@0"
            ]
        },
        {
            "x": -2,
            "y": 3,
            "z": 0,
            "elements": [
                "compactmachines3:wallbreakable@0"
            ]
        },
        {
            "x": -4,
            "y": -1,
            "z": 2,
            "elements": [
                "compactmachines3:wallbreakable@0"
            ]
        },
        {
            "x": 1,
            "y": 1,
            "z": -3,
            "elements": [
                "compactmachines3:wallbreakable@0"
            ]
        },
        {
            "x": -2,
            "y": -2,
            "z": 3,
            "elements": [
                "compactmachines3:wallbreakable@0"
            ]
        },
        {
            "x": 2,
            "y": -5,
            "z": 0,
            "elements": [
                "compactmachines3:wallbreakable@0"
            ]
        },
        {
            "x": 5,
            "y": -1,
            "z": 1,
            "elements": [
                "compactmachines3:wall@0"
            ]
        },
        {
            "x": -2,
            "y": 2,
            "z": 0,
            "elements": [
                "compactmachines3:wallbreakable@0"
            ]
        },
        {
            "x": 1,
            "y": -3,
            "z": 3,
            "elements": [
                "compactmachines3:wallbreakable@0"
            ]
        },
        {
            "x": -4,
            "y": -2,
            "z": -2,
            "elements": [
                "compactmachines3:wallbreakable@0"
            ]
        },
        {
            "x": -1,
            "y": 4,
            "z": 0,
            "elements": [
                "compactmachines3:wall@0"
            ]
        },
        {
            "x": 1,
            "y": -1,
            "z": -5,
            "elements": [
                "compactmachines3:wall@0"
            ]
        },
        {
            "x": 1,
            "y": -1,
            "z": 0,
            "elements": [
                "modularmachinery:blockinputbus@0"
            ]
        },
        {
            "x": -2,
            "y": 1,
            "z": 0,
            "elements": [
                "compactmachines3:wallbreakable@0"
            ]
        },
        {
            "x": 4,
            "y": 0,
            "z": -2,
            "elements": [
                "compactmachines3:wallbreakable@0"
            ]
        },
        {
            "x": 5,
            "y": 0,
            "z": -1,
            "elements": [
                "compactmachines3:wall@0"
            ]
        },
        {
            "x": 1,
            "y": -2,
            "z": -5,
            "elements": [
                "compactmachines3:wall@0"
            ]
        },
        {
            "x": -4,
            "y": -1,
            "z": -2,
            "elements": [
                "compactmachines3:wallbreakable@0"
            ]
        },
        {
            "x": 3,
            "y": 0,
            "z": 2,
            "elements": [
                "compactmachines3:wallbreakable@0"
            ]
        },
        {
            "x": 2,
            "y": -2,
            "z": 2,
            "elements": [
                "compactmachines3:wallbreakable@0"
            ]
        },
        {
            "x": -2,
            "y": 0,
            "z": -3,
            "elements": [
                "compactmachines3:wallbreakable@0"
            ]
        },
        {
            "x": -1,
            "y": -2,
            "z": 5,
            "elements": [
                "compactmachines3:wall@0"
            ]
        },
        {
            "x": -3,
            "y": 0,
            "z": -2,
            "elements": [
                "compactmachines3:wallbreakable@0"
            ]
        },
        {
            "x": 2,
            "y": -1,
            "z": 2,
            "elements": [
                "compactmachines3:wallbreakable@0"
            ]
        },
        {
            "x": 0,
            "y": 1,
            "z": 2,
            "elements": [
                "compactmachines3:wallbreakable@0"
            ]
        },
        {
            "x": 3,
            "y": -3,
            "z": 0,
            "elements": [
                "compactmachines3:wallbreakable@0"
            ]
        },
        {
            "x": 0,
            "y": 0,
            "z": -5,
            "elements": [
                "compactmachines3:wall@0"
            ]
        },
        {
            "x": -1,
            "y": -1,
            "z": 5,
            "elements": [
                "compactmachines3:wall@0"
            ]
        },
        {
            "x": 2,
            "y": 0,
            "z": 3,
            "elements": [
                "compactmachines3:wallbreakable@0"
            ]
        },
        {
            "x": 2,
            "y": -1,
            "z": -2,
            "elements": [
                "compactmachines3:wallbreakable@0"
            ]
        },
        {
            "x": -3,
            "y": 0,
            "z": 2,
            "elements": [
                "compactmachines3:wallbreakable@0"
            ]
        },
        {
            "x": 0,
            "y": 3,
            "z": 2,
            "elements": [
                "compactmachines3:wallbreakable@0"
            ]
        },
        {
            "x": 2,
            "y": -1,
            "z": 3,
            "elements": [
                "compactmachines3:wallbreakable@0"
            ]
        },
        {
            "x": -1,
            "y": -4,
            "z": -2,
            "elements": [
                "compactmachines3:wallbreakable@0"
            ]
        },
        {
            "x": 0,
            "y": 0,
            "z": 5,
            "elements": [
                "compactmachines3:wall@0"
            ]
        },
        {
            "x": -1,
            "y": -1,
            "z": -5,
            "elements": [
                "compactmachines3:wall@0"
            ]
        },
        {
            "x": 1,
            "y": 4,
            "z": 0,
            "elements": [
                "compactmachines3:wall@0"
            ]
        },
        {
            "x": 1,
            "y": -6,
            "z": 0,
            "elements": [
                "compactmachines3:wall@0"
            ]
        },
        {
            "x": -2,
            "y": -4,
            "z": 0,
            "elements": [
                "compactmachines3:wallbreakable@0"
            ]
        },
        {
            "x": 2,
            "y": -2,
            "z": -2,
            "elements": [
                "compactmachines3:wallbreakable@0"
            ]
        },
        {
            "x": -1,
            "y": -3,
            "z": -2,
            "elements": [
                "compactmachines3:wallbreakable@0"
            ]
        },
        {
            "x": -2,
            "y": -3,
            "z": 0,
            "elements": [
                "compactmachines3:wallbreakable@0"
            ]
        },
        {
            "x": 0,
            "y": 2,
            "z": 2,
            "elements": [
                "compactmachines3:wallbreakable@0"
            ]
        },
        {
            "x": -1,
            "y": -2,
            "z": -5,
            "elements": [
                "compactmachines3:wall@0"
            ]
        },
        {
            "x": -1,
            "y": 1,
            "z": -2,
            "elements": [
                "compactmachines3:wallbreakable@0"
            ]
        },
        {
            "x": -2,
            "y": 0,
            "z": 2,
            "elements": [
                "compactmachines3:wallbreakable@0"
            ]
        },
        {
            "x": -1,
            "y": 3,
            "z": 2,
            "elements": [
                "compactmachines3:wallbreakable@0"
            ]
        },
        {
            "x": 1,
            "y": -2,
            "z": 5,
            "elements": [
                "compactmachines3:wall@0"
            ]
        },
        {
            "x": 0,
            "y": -4,
            "z": -2,
            "elements": [
                "compactmachines3:wallbreakable@0"
            ]
        },
        {
            "x": 2,
            "y": -2,
            "z": 4,
            "elements": [
                "compactmachines3:wallbreakable@0"
            ]
        },
        {
            "x": 0,
            "y": 3,
            "z": -2,
            "elements": [
                "compactmachines3:wallbreakable@0"
            ]
        },
        {
            "x": 2,
            "y": -1,
            "z": 4,
            "elements": [
                "compactmachines3:wallbreakable@0"
            ]
        },
        {
            "x": -1,
            "y": -4,
            "z": 2,
            "elements": [
                "compactmachines3:wallbreakable@0"
            ]
        },
        {
            "x": -4,
            "y": 1,
            "z": 0,
            "elements": [
                "compactmachines3:wallbreakable@0"
            ]
        },
        {
            "x": 0,
            "y": 1,
            "z": 4,
            "elements": [
                "compactmachines3:wallbreakable@0"
            ]
        },
        {
            "x": -1,
            "y": -3,
            "z": 2,
            "elements": [
                "compactmachines3:wallbreakable@0"
            ]
        },
        {
            "x": 2,
            "y": 3,
            "z": 0,
            "elements": [
                "compactmachines3:wallbreakable@0"
            ]
        },
        {
            "x": 0,
            "y": 2,
            "z": -2,
            "elements": [
                "compactmachines3:wallbreakable@0"
            ]
        },
        {
            "x": -1,
            "y": 2,
            "z": 2,
            "elements": [
                "compactmachines3:wallbreakable@0"
            ]
        },
        {
            "x": 1,
            "y": -1,
            "z": 5,
            "elements": [
                "compactmachines3:wall@0"
            ]
        },
        {
            "x": -3,
            "y": -3,
            "z": 0,
            "elements": [
                "compactmachines3:wallbreakable@0"
            ]
        },
        {
            "x": -1,
            "y": -3,
            "z": -4,
            "elements": [
                "compactmachines3:wallbreakable@0"
            ]
        },
        {
            "x": 0,
            "y": -3,
            "z": -2,
            "elements": [
                "compactmachines3:wallbreakable@0"
            ]
        },
        {
            "x": 2,
            "y": -1,
            "z": -4,
            "elements": [
                "compactmachines3:wallbreakable@0"
            ]
        },
        {
            "x": 1,
            "y": -6,
            "z": -1,
            "elements": [
                "compactmachines3:wall@0"
            ]
        },
        {
            "x": 0,
            "y": 1,
            "z": -2,
            "elements": [
                "compactmachines3:wallbreakable@0"
            ]
        },
        {
            "x": 5,
            "y": 0,
            "z": 0,
            "elements": [
                "compactmachines3:wall@0"
            ]
        },
        {
            "x": -1,
            "y": 3,
            "z": -2,
            "elements": [
                "compactmachines3:wallbreakable@0"
            ]
        },
        {
            "x": -2,
            "y": -4,
            "z": -1,
            "elements": [
                "compactmachines3:wallbreakable@0"
            ]
        },
        {
            "x": 2,
            "y": 2,
            "z": 0,
            "elements": [
                "compactmachines3:wallbreakable@0"
            ]
        },
        {
            "x": 0,
            "y": -4,
            "z": 2,
            "elements": [
                "compactmachines3:wallbreakable@0"
            ]
        },
        {
            "x": 1,
            "y": -4,
            "z": -2,
            "elements": [
                "compactmachines3:wallbreakable@0"
            ]
        },
        {
            "x": -5,
            "y": -1,
            "z": -1,
            "elements": [
                "compactmachines3:wall@0"
            ]
        },
        {
            "x": -2,
            "y": -3,
            "z": -1,
            "elements": [
                "compactmachines3:wallbreakable@0"
            ]
        },
        {
            "x": -1,
            "y": 1,
            "z": 2,
            "elements": [
                "compactmachines3:wallbreakable@0"
            ]
        },
        {
            "x": 4,
            "y": -3,
            "z": 0,
            "elements": [
                "compactmachines3:wallbreakable@0"
            ]
        },
        {
            "x": 2,
            "y": 1,
            "z": 0,
            "elements": [
                "compactmachines3:wallbreakable@0"
            ]
        },
        {
            "x": 0,
            "y": -3,
            "z": 2,
            "elements": [
                "compactmachines3:wallbreakable@0"
            ]
        },
        {
            "x": -1,
            "y": 2,
            "z": -2,
            "elements": [
                "compactmachines3:wallbreakable@0"
            ]
        },
        {
            "x": -5,
            "y": -2,
            "z": -1,
            "elements": [
                "compactmachines3:wall@0"
            ]
        },
        {
            "x": 4,
            "y": 1,
            "z": 1,
            "elements": [
                "compactmachines3:wallbreakable@0"
            ]
        },
        {
            "x": 1,
            "y": -3,
            "z": -2,
            "elements": [
                "compactmachines3:wallbreakable@0"
            ]
        },
        {
            "x": 1,
            "y": -5,
            "z": 2,
            "elements": [
                "compactmachines3:wallbreakable@0"
            ]
        },
        {
            "x": -4,
            "y": 1,
            "z": -1,
            "elements": [
                "compactmachines3:wallbreakable@0"
            ]
        },
        {
            "x": -4,
            "y": 0,
            "z": 2,
            "elements": [
                "compactmachines3:wallbreakable@0"
            ]
        },
        {
            "x": 3,
            "y": -1,
            "z": -2,
            "elements": [
                "compactmachines3:wallbreakable@0"
            ]
        },
        {
            "x": 1,
            "y": 3,
            "z": 2,
            "elements": [
                "compactmachines3:wallbreakable@0"
            ]
        },
        {
            "x": -5,
            "y": 0,
            "z": 1,
            "elements": [
                "compactmachines3:wall@0"
            ]
        },
        {
            "x": 1,
            "y": 1,
            "z": -2,
            "elements": [
                "compactmachines3:wallbreakable@0"
            ]
        },
        {
            "x": -2,
            "y": -2,
            "z": 2,
            "elements": [
                "compactmachines3:wallbreakable@0"
            ]
        },
        {
            "x": 2,
            "y": 2,
            "z": -1,
            "elements": [
                "compactmachines3:wallbreakable@0"
            ]
        },
        {
            "x": 1,
            "y": -4,
            "z": 2,
            "elements": [
                "compactmachines3:wallbreakable@0"
            ]
        },
        {
            "x": -3,
            "y": -3,
            "z": 1,
            "elements": [
                "compactmachines3:wallbreakable@0"
            ]
        },
        {
            "x": 0,
            "y": -1,
            "z": -5,
            "elements": [
                "compactmachines3:tunnel"
            ]
        },
        {
            "x": -1,
            "y": 0,
            "z": 5,
            "elements": [
                "compactmachines3:wall@0"
            ]
        },
        {
            "x": 1,
            "y": 4,
            "z": 1,
            "elements": [
                "compactmachines3:wall@0"
            ]
        },
        {
            "x": 3,
            "y": -2,
            "z": -2,
            "elements": [
                "compactmachines3:wallbreakable@0"
            ]
        },
        {
            "x": -2,
            "y": -1,
            "z": 2,
            "elements": [
                "compactmachines3:wallbreakable@0"
            ]
        },
        {
            "x": -2,
            "y": -5,
            "z": -1,
            "elements": [
                "compactmachines3:wallbreakable@0"
            ]
        },
        {
            "x": 0,
            "y": -6,
            "z": 0,
            "elements": [
                "compactmachines3:tunnel"
            ]
        },
        {
            "x": 1,
            "y": -5,
            "z": -2,
            "elements": [
                "compactmachines3:wallbreakable@0"
            ]
        },
        {
            "x": 1,
            "y": -3,
            "z": 2,
            "elements": [
                "compactmachines3:wallbreakable@0"
            ]
        },
        {
            "x": 3,
            "y": 1,
            "z": -1,
            "elements": [
                "compactmachines3:wallbreakable@0"
            ]
        },
        {
            "x": 1,
            "y": 2,
            "z": 2,
            "elements": [
                "compactmachines3:wallbreakable@0"
            ]
        },
        {
            "x": -5,
            "y": 0,
            "z": 0,
            "elements": [
                "compactmachines3:wall@0"
            ]
        },
        {
            "x": 2,
            "y": 3,
            "z": -1,
            "elements": [
                "compactmachines3:wallbreakable@0"
            ]
        },
        {
            "x": 0,
            "y": -2,
            "z": -5,
            "elements": [
                "compactmachines3:wall@0"
            ]
        },
        {
            "x": 0,
            "y": 4,
            "z": -1,
            "elements": [
                "compactmachines3:wall@0"
            ]
        },
        {
            "x": 5,
            "y": -1,
            "z": -1,
            "elements": [
                "compactmachines3:wall@0"
            ]
        },
        {
            "x": 1,
            "y": 3,
            "z": -2,
            "elements": [
                "compactmachines3:wallbreakable@0"
            ]
        },
        {
            "x": -4,
            "y": -3,
            "z": 1,
            "elements": [
                "compactmachines3:wallbreakable@0"
            ]
        },
        {
            "x": 1,
            "y": 1,
            "z": 2,
            "elements": [
                "compactmachines3:wallbreakable@0"
            ]
        },
        {
            "x": -2,
            "y": -2,
            "z": -2,
            "elements": [
                "compactmachines3:wallbreakable@0"
            ]
        },
        {
            "x": 4,
            "y": -3,
            "z": -1,
            "elements": [
                "compactmachines3:wallbreakable@0"
            ]
        },
        {
            "x": -2,
            "y": 0,
            "z": -2,
            "elements": [
                "compactmachines3:wallbreakable@0"
            ]
        },
        {
            "x": 5,
            "y": -2,
            "z": -1,
            "elements": [
                "compactmachines3:wall@0"
            ]
        },
        {
            "x": 3,
            "y": -3,
            "z": 1,
            "elements": [
                "compactmachines3:wallbreakable@0"
            ]
        },
        {
            "x": 1,
            "y": 0,
            "z": -5,
            "elements": [
                "compactmachines3:wall@0"
            ]
        },
        {
            "x": 1,
            "y": 2,
            "z": -2,
            "elements": [
                "compactmachines3:wallbreakable@0"
            ]
        },
        {
            "x": -2,
            "y": -1,
            "z": -2,
            "elements": [
                "compactmachines3:wallbreakable@0"
            ]
        },
        {
            "x": -1,
            "y": -5,
            "z": 2,
            "elements": [
                "compactmachines3:wallbreakable@0"
            ]
        },
        {
            "x": -1,
            "y": -6,
            "z": 1,
            "elements": [
                "compactmachines3:wall@0"
            ]
        },
        {
            "x": 0,
            "y": -6,
            "z": -1,
            "elements": [
                "compactmachines3:wall@0"
            ]
        },
        {
            "x": -2,
            "y": -2,
            "z": -3,
            "elements": [
                "compactmachines3:wallbreakable@0"
            ]
        },
        {
            "x": 1,
            "y": 1,
            "z": 3,
            "elements": [
                "compactmachines3:wallbreakable@0"
            ]
        },
        {
            "x": -1,
            "y": 4,
            "z": -1,
            "elements": [
                "compactmachines3:wall@0"
            ]
        },
        {
            "x": -2,
            "y": -2,
            "z": 4,
            "elements": [
                "compactmachines3:wallbreakable@0"
            ]
        },
        {
            "x": 1,
            "y": 1,
            "z": -4,
            "elements": [
                "compactmachines3:wallbreakable@0"
            ]
        },
        {
            "x": 2,
            "y": 1,
            "z": -1,
            "elements": [
                "compactmachines3:wallbreakable@0"
            ]
        },
        {
            "x": 2,
            "y": -4,
            "z": 1,
            "elements": [
                "compactmachines3:wallbreakable@0"
            ]
        },
        {
            "x": -3,
            "y": -2,
            "z": -2,
            "elements": [
                "compactmachines3:wallbreakable@0"
            ]
        },
        {
            "x": 4,
            "y": -1,
            "z": 2,
            "elements": [
                "compactmachines3:wallbreakable@0"
            ]
        },
        {
            "x": 0,
            "y": -6,
            "z": 1,
            "elements": [
                "compactmachines3:wall@0"
            ]
        },
        {
            "x": 2,
            "y": -3,
            "z": 1,
            "elements": [
                "compactmachines3:wallbreakable@0"
            ]
        },
        {
            "x": -1,
            "y": 4,
            "z": 1,
            "elements": [
                "compactmachines3:wall@0"
            ]
        },
        {
            "x": -3,
            "y": -1,
            "z": -2,
            "elements": [
                "compactmachines3:wallbreakable@0"
            ]
        },
        {
            "x": 4,
            "y": -2,
            "z": 2,
            "elements": [
                "compactmachines3:wallbreakable@0"
            ]
        },
        {
            "x": -3,
            "y": 1,
            "z": 1,
            "elements": [
                "compactmachines3:wallbreakable@0"
            ]
        },
        {
            "x": 2,
            "y": 0,
            "z": 2,
            "elements": [
                "compactmachines3:wallbreakable@0"
            ]
        },
        {
            "x": 3,
            "y": -2,
            "z": 2,
            "elements": [
                "compactmachines3:wallbreakable@0"
            ]
        },
        {
            "x": -3,
            "y": 1,
            "z": -1,
            "elements": [
                "compactmachines3:wallbreakable@0"
            ]
        },
        {
            "x": 4,
            "y": -1,
            "z": -2,
            "elements": [
                "compactmachines3:wallbreakable@0"
            ]
        },
        {
            "x": -1,
            "y": 1,
            "z": 4,
            "elements": [
                "compactmachines3:wallbreakable@0"
            ]
        },
        {
            "x": -4,
            "y": 0,
            "z": -2,
            "elements": [
                "compactmachines3:wallbreakable@0"
            ]
        },
        {
            "x": 3,
            "y": -1,
            "z": 2,
            "elements": [
                "compactmachines3:wallbreakable@0"
            ]
        },
        {
            "x": 2,
            "y": -3,
            "z": -1,
            "elements": [
                "compactmachines3:wallbreakable@0"
            ]
        },
        {
            "x": 4,
            "y": -2,
            "z": -2,
            "elements": [
                "compactmachines3:wallbreakable@0"
            ]
        },
        {
            "x": 1,
            "y": -3,
            "z": 4,
            "elements": [
                "compactmachines3:wallbreakable@0"
            ]
        },
        {
            "x": -2,
            "y": -1,
            "z": -3,
            "elements": [
                "compactmachines3:wallbreakable@0"
            ]
        },
        {
            "x": 0,
            "y": -3,
            "z": -4,
            "elements": [
                "compactmachines3:wallbreakable@0"
            ]
        },
        {
            "x": 2,
            "y": -4,
            "z": -1,
            "elements": [
                "compactmachines3:wallbreakable@0"
            ]
        },
        {
            "x": 0,
            "y": -1,
            "z": -1,
            "elements": [
                "modularmachinery:blockinputbus@0"
            ]
        },
        {
            "x": -1,
            "y": 1,
            "z": -4,
            "elements": [
                "compactmachines3:wallbreakable@0"
            ]
        },
        {
            "x": 2,
            "y": -5,
            "z": 1,
            "elements": [
                "compactmachines3:wallbreakable@0"
            ]
        },
        {
            "x": -2,
            "y": 2,
            "z": 1,
            "elements": [
                "compactmachines3:wallbreakable@0"
            ]
        },
        {
            "x": 0,
            "y": -3,
            "z": 4,
            "elements": [
                "compactmachines3:wallbreakable@0"
            ]
        },
        {
            "x": 2,
            "y": 0,
            "z": -4,
            "elements": [
                "compactmachines3:wallbreakable@0"
            ]
        },
        {
            "x": 2,
            "y": -5,
            "z": -1,
            "elements": [
                "compactmachines3:wallbreakable@0"
            ]
        },
        {
            "x": -2,
            "y": 3,
            "z": -1,
            "elements": [
                "compactmachines3:wallbreakable@0"
            ]
        },
        {
            "x": 1,
            "y": -3,
            "z": -4,
            "elements": [
                "compactmachines3:wallbreakable@0"
            ]
        },
        {
            "x": -2,
            "y": 3,
            "z": 1,
            "elements": [
                "compactmachines3:wallbreakable@0"
            ]
        },
        {
            "x": 0,
            "y": -5,
            "z": 2,
            "elements": [
                "compactmachines3:wallbreakable@0"
            ]
        },
        {
            "x": 0,
            "y": 1,
            "z": -4,
            "elements": [
                "compactmachines3:wallbreakable@0"
            ]
        },
        {
            "x": -3,
            "y": -2,
            "z": 2,
            "elements": [
                "compactmachines3:wallbreakable@0"
            ]
        },
        {
            "x": -5,
            "y": -2,
            "z": 0,
            "elements": [
                "compactmachines3:wall@0"
            ]
        },
        {
            "x": 2,
            "y": -2,
            "z": -4,
            "elements": [
                "compactmachines3:wallbreakable@0"
            ]
        },
        {
            "x": 0,
            "y": -1,
            "z": 1,
            "elements": [
                "modularmachinery:blockinputbus@0"
            ]
        },
        {
            "x": -3,
            "y": -1,
            "z": 2,
            "elements": [
                "compactmachines3:wallbreakable@0"
            ]
        },
        {
            "x": -1,
            "y": -3,
            "z": 4,
            "elements": [
                "compactmachines3:wallbreakable@0"
            ]
        },
        {
            "x": 0,
            "y": -5,
            "z": -2,
            "elements": [
                "compactmachines3:wallbreakable@0"
            ]
        },
        {
            "x": 2,
            "y": 0,
            "z": -2,
            "elements": [
                "compactmachines3:wallbreakable@0"
            ]
        },
        {
            "x": 4,
            "y": 1,
            "z": 0,
            "elements": [
                "compactmachines3:wallbreakable@0"
            ]
        },
        {
            "x": -2,
            "y": -1,
            "z": 4,
            "elements": [
                "compactmachines3:wallbreakable@0"
            ]
        },
        {
            "x": -5,
            "y": -1,
            "z": 0,
            "elements": [
                "compactmachines3:tunnel"
            ]
        },
        {
            "x": -2,
            "y": 0,
            "z": 4,
            "elements": [
                "compactmachines3:wallbreakable@0"
            ]
        },
        {
            "x": -2,
            "y": 1,
            "z": 1,
            "elements": [
                "compactmachines3:wallbreakable@0"
            ]
        },
        {
            "x": -2,
            "y": 1,
            "z": -1,
            "elements": [
                "compactmachines3:wallbreakable@0"
            ]
        },
        {
            "x": 2,
            "y": -2,
            "z": -3,
            "elements": [
                "compactmachines3:wallbreakable@0"
            ]
        },
        {
            "x": 1,
            "y": 0,
            "z": 5,
            "elements": [
                "compactmachines3:wall@0"
            ]
        },
        {
            "x": 3,
            "y": -3,
            "z": -1,
            "elements": [
                "compactmachines3:wallbreakable@0"
            ]
        },
        {
            "x": 3,
            "y": 1,
            "z": 0,
            "elements": [
                "compactmachines3:wallbreakable@0"
            ]
        },
        {
            "x": 2,
            "y": -2,
            "z": 3,
            "elements": [
                "compactmachines3:wallbreakable@0"
            ]
        },
        {
            "x": -2,
            "y": -5,
            "z": 0,
            "elements": [
                "compactmachines3:wallbreakable@0"
            ]
        },
        {
            "x": 0,
            "y": 1,
            "z": 3,
            "elements": [
                "compactmachines3:wallbreakable@0"
            ]
        },
        {
            "x": 0,
            "y": -2,
            "z": 5,
            "elements": [
                "compactmachines3:wall@0"
            ]
        },
        {
            "x": -2,
            "y": -3,
            "z": 1,
            "elements": [
                "compactmachines3:wallbreakable@0"
            ]
        },
        {
            "x": 1,
            "y": -6,
            "z": 1,
            "elements": [
                "compactmachines3:wall@0"
            ]
        },
        {
            "x": -1,
            "y": -6,
            "z": 0,
            "elements": [
                "compactmachines3:wall@0"
            ]
        },
        {
            "x": -4,
            "y": 1,
            "z": 1,
            "elements": [
                "compactmachines3:wallbreakable@0"
            ]
        },
        {
            "x": -1,
            "y": -3,
            "z": -3,
            "elements": [
                "compactmachines3:wallbreakable@0"
            ]
        },
        {
            "x": -2,
            "y": 2,
            "z": -1,
            "elements": [
                "compactmachines3:wallbreakable@0"
            ]
        },
        {
            "x": 2,
            "y": -1,
            "z": -3,
            "elements": [
                "compactmachines3:wallbreakable@0"
            ]
        },
        {
            "x": 0,
            "y": -1,
            "z": 5,
            "elements": [
                "compactmachines3:tunnel"
            ]
        },
        {
            "x": 4,
            "y": 1,
            "z": -1,
            "elements": [
                "compactmachines3:wallbreakable@0"
            ]
        },
        {
            "x": -4,
            "y": -3,
            "z": 0,
            "elements": [
                "compactmachines3:wallbreakable@0"
            ]
        },
        {
            "x": -5,
            "y": -2,
            "z": 1,
            "elements": [
                "compactmachines3:wall@0"
            ]
        },
        {
            "x": -1,
            "y": 0,
            "z": -5,
            "elements": [
                "compactmachines3:wall@0"
            ]
        },
        {
            "x": -2,
            "y": -4,
            "z": 1,
            "elements": [
                "compactmachines3:wallbreakable@0"
            ]
        },
        {
            "x": 1,
            "y": 4,
            "z": -1,
            "elements": [
                "compactmachines3:wall@0"
            ]
        },
        {
            "x": -2,
            "y": -5,
            "z": 1,
            "elements": [
                "compactmachines3:wallbreakable@0"
            ]
        },
        {
            "x": 2,
            "y": 3,
            "z": 1,
            "elements": [
                "compactmachines3:wallbreakable@0"
            ]
        },
        {
            "x": -1,
            "y": 1,
            "z": 3,
            "elements": [
                "compactmachines3:wallbreakable@0"
            ]
        },
        {
            "x": 0,
            "y": -3,
            "z": 3,
            "elements": [
                "compactmachines3:wallbreakable@0"
            ]
        },
        {
            "x": 2,
            "y": 0,
            "z": -3,
            "elements": [
                "compactmachines3:wallbreakable@0"
            ]
        },
        {
            "x": 0,
            "y": 4,
            "z": 0,
            "elements": [
                "compactmachines3:tunnel"
            ]
        },
        {
            "x": 5,
            "y": -1,
            "z": 0,
            "elements": [
                "compactmachines3:tunnel"
            ]
        },
        {
            "x": 0,
            "y": -3,
            "z": -3,
            "elements": [
                "compactmachines3:wallbreakable@0"
            ]
        },
        {
            "x": 4,
            "y": -3,
            "z": 1,
            "elements": [
                "compactmachines3:wallbreakable@0"
            ]
        },
        {
            "x": -3,
            "y": -3,
            "z": -1,
            "elements": [
                "compactmachines3:wallbreakable@0"
            ]
        },
        {
            "x": 2,
            "y": 2,
            "z": 1,
            "elements": [
                "compactmachines3:wallbreakable@0"
            ]
        },
        {
            "x": 3,
            "y": 1,
            "z": 1,
            "elements": [
                "compactmachines3:wallbreakable@0"
            ]
        },
        {
            "x": -5,
            "y": -1,
            "z": 1,
            "elements": [
                "compactmachines3:wall@0"
            ]
        },
        {
            "x": 4,
            "y": 0,
            "z": 2,
            "elements": [
                "compactmachines3:wallbreakable@0"
            ]
        },
        {
            "x": -2,
            "y": 0,
            "z": 3,
            "elements": [
                "compactmachines3:wallbreakable@0"
            ]
        },
        {
            "x": -2,
            "y": -1,
            "z": -4,
            "elements": [
                "compactmachines3:wallbreakable@0"
            ]
        },
        {
            "x": -1,
            "y": 1,
            "z": -3,
            "elements": [
                "compactmachines3:wallbreakable@0"
            ]
        },
        {
            "x": 5,
            "y": -2,
            "z": 0,
            "elements": [
                "compactmachines3:wall@0"
            ]
        },
        {
            "x": -1,
            "y": -6,
            "z": -1,
            "elements": [
                "compactmachines3:wall@0"
            ]
        },
        {
            "x": -2,
            "y": -2,
            "z": -4,
            "elements": [
                "compactmachines3:wallbreakable@0"
            ]
        },
        {
            "x": -2,
            "y": -1,
            "z": 3,
            "elements": [
                "compactmachines3:wallbreakable@0"
            ]
        },
        {
            "x": 2,
            "y": -4,
            "z": 0,
            "elements": [
                "compactmachines3:wallbreakable@0"
            ]
        },
        {
            "x": -1,
            "y": -3,
            "z": 3,
            "elements": [
                "compactmachines3:wallbreakable@0"
            ]
        },
        {
            "x": -2,
            "y": 0,
            "z": -4,
            "elements": [
                "compactmachines3:wallbreakable@0"
            ]
        },
        {
            "x": 1,
            "y": 1,
            "z": 4,
            "elements": [
                "compactmachines3:wallbreakable@0"
            ]
        },
        {
            "x": -3,
            "y": 1,
            "z": 0,
            "elements": [
                "compactmachines3:wallbreakable@0"
            ]
        },
        {
            "x": 1,
            "y": -3,
            "z": -3,
            "elements": [
                "compactmachines3:wallbreakable@0"
            ]
        },
        {
            "x": -1,
            "y": -1,
            "z": 0,
            "elements": [
                "modularmachinery:blockinputbus@0"
            ]
        },
        {
            "x": -4,
            "y": -3,
            "z": -1,
            "elements": [
                "compactmachines3:wallbreakable@0"
            ]
        },
        {
            "x": 2,
            "y": -3,
            "z": 0,
            "elements": [
                "compactmachines3:wallbreakable@0"
            ]
        },
        {
            "x": 0,
            "y": 4,
            "z": 1,
            "elements": [
                "compactmachines3:wall@0"
            ]
        },
        {
            "x": 0,
            "y": 1,
            "z": -3,
            "elements": [
                "compactmachines3:wallbreakable@0"
            ]
        },
        {
            "x": 2,
            "y": 1,
            "z": 1,
            "elements": [
                "compactmachines3:wallbreakable@0"
            ]
        },
        {
            "x": 2,
            "y": 0,
            "z": 4,
            "elements": [
                "compactmachines3:wallbreakable@0"
            ]
        },
        {
            "x": -5,
            "y": 0,
            "z": -1,
            "elements": [
                "compactmachines3:wall@0"
            ]
        }
    ]
}